[17/Mar/2017 12:33:42] ERROR [/usr/local/lib64/python2.7/site-packages/django/core/handlers/base.py:256] Internal Server Error: /
Traceback (most recent call last):
  File "/usr/local/lib64/python2.7/site-packages/django/core/handlers/base.py", line 164, in get_response
    response = response.render()
  File "/usr/local/lib64/python2.7/site-packages/django/template/response.py", line 158, in render
    self.content = self.rendered_content
  File "/usr/local/lib64/python2.7/site-packages/django/template/response.py", line 135, in rendered_content
    content = template.render(context, self._request)
  File "/usr/local/lib64/python2.7/site-packages/django/template/backends/django.py", line 74, in render
    return self.template.render(context)
  File "/usr/local/lib64/python2.7/site-packages/django/template/base.py", line 210, in render
    return self._render(context)
  File "/usr/local/lib64/python2.7/site-packages/django/template/base.py", line 202, in _render
    return self.nodelist.render(context)
  File "/usr/local/lib64/python2.7/site-packages/django/template/base.py", line 905, in render
    bit = self.render_node(node, context)
  File "/usr/local/lib64/python2.7/site-packages/django/template/base.py", line 919, in render_node
    return node.render(context)
  File "/usr/local/lib64/python2.7/site-packages/django/template/loader_tags.py", line 135, in render
    return compiled_parent._render(context)
  File "/usr/local/lib64/python2.7/site-packages/django/template/base.py", line 202, in _render
    return self.nodelist.render(context)
  File "/usr/local/lib64/python2.7/site-packages/django/template/base.py", line 905, in render
    bit = self.render_node(node, context)
  File "/usr/local/lib64/python2.7/site-packages/django/template/base.py", line 919, in render_node
    return node.render(context)
  File "/usr/local/lib64/python2.7/site-packages/django/template/loader_tags.py", line 65, in render
    result = block.nodelist.render(context)
  File "/usr/local/lib64/python2.7/site-packages/django/template/base.py", line 905, in render
    bit = self.render_node(node, context)
  File "/usr/local/lib64/python2.7/site-packages/django/template/base.py", line 919, in render_node
    return node.render(context)
  File "/usr/local/lib64/python2.7/site-packages/django/template/loader_tags.py", line 65, in render
    result = block.nodelist.render(context)
  File "/usr/local/lib64/python2.7/site-packages/django/template/base.py", line 905, in render
    bit = self.render_node(node, context)
  File "/usr/local/lib64/python2.7/site-packages/django/template/base.py", line 919, in render_node
    return node.render(context)
  File "/usr/local/lib64/python2.7/site-packages/django/template/loader_tags.py", line 65, in render
    result = block.nodelist.render(context)
  File "/usr/local/lib64/python2.7/site-packages/django/template/base.py", line 905, in render
    bit = self.render_node(node, context)
  File "/usr/local/lib64/python2.7/site-packages/django/template/base.py", line 919, in render_node
    return node.render(context)
  File "/usr/local/lib64/python2.7/site-packages/django/template/defaulttags.py", line 329, in render
    return nodelist.render(context)
  File "/usr/local/lib64/python2.7/site-packages/django/template/base.py", line 905, in render
    bit = self.render_node(node, context)
  File "/usr/local/lib64/python2.7/site-packages/django/template/base.py", line 919, in render_node
    return node.render(context)
  File "/usr/local/lib64/python2.7/site-packages/django/template/base.py", line 959, in render
    output = self.filter_expression.resolve(context)
  File "/usr/local/lib64/python2.7/site-packages/django/template/base.py", line 648, in resolve
    obj = self.var.resolve(context)
  File "/usr/local/lib64/python2.7/site-packages/django/template/base.py", line 789, in resolve
    value = self._resolve_lookup(context)
  File "/usr/local/lib64/python2.7/site-packages/django/template/base.py", line 849, in _resolve_lookup
    current = current()
  File "/usr/local/lib64/python2.7/site-packages/django/template/loader_tags.py", line 79, in super
    return mark_safe(self.render(self.context))
  File "/usr/local/lib64/python2.7/site-packages/django/template/loader_tags.py", line 65, in render
    result = block.nodelist.render(context)
  File "/usr/local/lib64/python2.7/site-packages/django/template/base.py", line 905, in render
    bit = self.render_node(node, context)
  File "/usr/local/lib64/python2.7/site-packages/django/template/base.py", line 919, in render_node
    return node.render(context)
  File "/usr/local/lib64/python2.7/site-packages/django/template/defaulttags.py", line 329, in render
    return nodelist.render(context)
  File "/usr/local/lib64/python2.7/site-packages/django/template/base.py", line 905, in render
    bit = self.render_node(node, context)
  File "/usr/local/lib64/python2.7/site-packages/django/template/base.py", line 919, in render_node
    return node.render(context)
  File "/usr/local/lib64/python2.7/site-packages/django/template/defaulttags.py", line 329, in render
    return nodelist.render(context)
  File "/usr/local/lib64/python2.7/site-packages/django/template/base.py", line 905, in render
    bit = self.render_node(node, context)
  File "/usr/local/lib64/python2.7/site-packages/django/template/base.py", line 919, in render_node
    return node.render(context)
  File "/usr/local/lib64/python2.7/site-packages/django/template/defaulttags.py", line 493, in render
    url = reverse(view_name, args=args, kwargs=kwargs, current_app=current_app)
  File "/usr/local/lib64/python2.7/site-packages/django/core/urlresolvers.py", line 578, in reverse
    return force_text(iri_to_uri(resolver._reverse_with_prefix(view, prefix, *args, **kwargs)))
  File "/usr/local/lib64/python2.7/site-packages/django/core/urlresolvers.py", line 432, in _reverse_with_prefix
    self._populate()
  File "/usr/local/lib64/python2.7/site-packages/django/core/urlresolvers.py", line 307, in _populate
    for name in pattern.reverse_dict:
  File "/usr/local/lib64/python2.7/site-packages/django/core/urlresolvers.py", line 337, in reverse_dict
    self._populate()
  File "/usr/local/lib64/python2.7/site-packages/django/core/urlresolvers.py", line 307, in _populate
    for name in pattern.reverse_dict:
  File "/usr/local/lib64/python2.7/site-packages/django/core/urlresolvers.py", line 337, in reverse_dict
    self._populate()
  File "/usr/local/lib64/python2.7/site-packages/django/core/urlresolvers.py", line 284, in _populate
    for pattern in reversed(self.url_patterns):
  File "/usr/local/lib64/python2.7/site-packages/django/core/urlresolvers.py", line 410, in url_patterns
    raise ImproperlyConfigured(msg.format(name=self.urlconf_name))
ImproperlyConfigured: The included urlconf 'None' does not appear to have any patterns in it. If you see valid patterns in the file then the issue is probably caused by a circular import.
[17/Mar/2017 12:33:44] ERROR [/usr/local/lib64/python2.7/site-packages/django/core/handlers/base.py:256] Internal Server Error: /
Traceback (most recent call last):
  File "/usr/local/lib64/python2.7/site-packages/django/core/handlers/base.py", line 164, in get_response
    response = response.render()
  File "/usr/local/lib64/python2.7/site-packages/django/template/response.py", line 158, in render
    self.content = self.rendered_content
  File "/usr/local/lib64/python2.7/site-packages/django/template/response.py", line 135, in rendered_content
    content = template.render(context, self._request)
  File "/usr/local/lib64/python2.7/site-packages/django/template/backends/django.py", line 74, in render
    return self.template.render(context)
  File "/usr/local/lib64/python2.7/site-packages/django/template/base.py", line 210, in render
    return self._render(context)
  File "/usr/local/lib64/python2.7/site-packages/django/template/base.py", line 202, in _render
    return self.nodelist.render(context)
  File "/usr/local/lib64/python2.7/site-packages/django/template/base.py", line 905, in render
    bit = self.render_node(node, context)
  File "/usr/local/lib64/python2.7/site-packages/django/template/base.py", line 919, in render_node
    return node.render(context)
  File "/usr/local/lib64/python2.7/site-packages/django/template/loader_tags.py", line 135, in render
    return compiled_parent._render(context)
  File "/usr/local/lib64/python2.7/site-packages/django/template/base.py", line 202, in _render
    return self.nodelist.render(context)
  File "/usr/local/lib64/python2.7/site-packages/django/template/base.py", line 905, in render
    bit = self.render_node(node, context)
  File "/usr/local/lib64/python2.7/site-packages/django/template/base.py", line 919, in render_node
    return node.render(context)
  File "/usr/local/lib64/python2.7/site-packages/django/template/loader_tags.py", line 65, in render
    result = block.nodelist.render(context)
  File "/usr/local/lib64/python2.7/site-packages/django/template/base.py", line 905, in render
    bit = self.render_node(node, context)
  File "/usr/local/lib64/python2.7/site-packages/django/template/base.py", line 919, in render_node
    return node.render(context)
  File "/usr/local/lib64/python2.7/site-packages/django/template/loader_tags.py", line 65, in render
    result = block.nodelist.render(context)
  File "/usr/local/lib64/python2.7/site-packages/django/template/base.py", line 905, in render
    bit = self.render_node(node, context)
  File "/usr/local/lib64/python2.7/site-packages/django/template/base.py", line 919, in render_node
    return node.render(context)
  File "/usr/local/lib64/python2.7/site-packages/django/template/loader_tags.py", line 65, in render
    result = block.nodelist.render(context)
  File "/usr/local/lib64/python2.7/site-packages/django/template/base.py", line 905, in render
    bit = self.render_node(node, context)
  File "/usr/local/lib64/python2.7/site-packages/django/template/base.py", line 919, in render_node
    return node.render(context)
  File "/usr/local/lib64/python2.7/site-packages/django/template/defaulttags.py", line 329, in render
    return nodelist.render(context)
  File "/usr/local/lib64/python2.7/site-packages/django/template/base.py", line 905, in render
    bit = self.render_node(node, context)
  File "/usr/local/lib64/python2.7/site-packages/django/template/base.py", line 919, in render_node
    return node.render(context)
  File "/usr/local/lib64/python2.7/site-packages/django/template/base.py", line 959, in render
    output = self.filter_expression.resolve(context)
  File "/usr/local/lib64/python2.7/site-packages/django/template/base.py", line 648, in resolve
    obj = self.var.resolve(context)
  File "/usr/local/lib64/python2.7/site-packages/django/template/base.py", line 789, in resolve
    value = self._resolve_lookup(context)
  File "/usr/local/lib64/python2.7/site-packages/django/template/base.py", line 849, in _resolve_lookup
    current = current()
  File "/usr/local/lib64/python2.7/site-packages/django/template/loader_tags.py", line 79, in super
    return mark_safe(self.render(self.context))
  File "/usr/local/lib64/python2.7/site-packages/django/template/loader_tags.py", line 65, in render
    result = block.nodelist.render(context)
  File "/usr/local/lib64/python2.7/site-packages/django/template/base.py", line 905, in render
    bit = self.render_node(node, context)
  File "/usr/local/lib64/python2.7/site-packages/django/template/base.py", line 919, in render_node
    return node.render(context)
  File "/usr/local/lib64/python2.7/site-packages/django/template/defaulttags.py", line 329, in render
    return nodelist.render(context)
  File "/usr/local/lib64/python2.7/site-packages/django/template/base.py", line 905, in render
    bit = self.render_node(node, context)
  File "/usr/local/lib64/python2.7/site-packages/django/template/base.py", line 919, in render_node
    return node.render(context)
  File "/usr/local/lib64/python2.7/site-packages/django/template/defaulttags.py", line 329, in render
    return nodelist.render(context)
  File "/usr/local/lib64/python2.7/site-packages/django/template/base.py", line 905, in render
    bit = self.render_node(node, context)
  File "/usr/local/lib64/python2.7/site-packages/django/template/base.py", line 919, in render_node
    return node.render(context)
  File "/usr/local/lib64/python2.7/site-packages/django/template/defaulttags.py", line 493, in render
    url = reverse(view_name, args=args, kwargs=kwargs, current_app=current_app)
  File "/usr/local/lib64/python2.7/site-packages/django/core/urlresolvers.py", line 578, in reverse
    return force_text(iri_to_uri(resolver._reverse_with_prefix(view, prefix, *args, **kwargs)))
  File "/usr/local/lib64/python2.7/site-packages/django/core/urlresolvers.py", line 432, in _reverse_with_prefix
    self._populate()
  File "/usr/local/lib64/python2.7/site-packages/django/core/urlresolvers.py", line 307, in _populate
    for name in pattern.reverse_dict:
  File "/usr/local/lib64/python2.7/site-packages/django/core/urlresolvers.py", line 337, in reverse_dict
    self._populate()
  File "/usr/local/lib64/python2.7/site-packages/django/core/urlresolvers.py", line 307, in _populate
    for name in pattern.reverse_dict:
  File "/usr/local/lib64/python2.7/site-packages/django/core/urlresolvers.py", line 337, in reverse_dict
    self._populate()
  File "/usr/local/lib64/python2.7/site-packages/django/core/urlresolvers.py", line 284, in _populate
    for pattern in reversed(self.url_patterns):
  File "/usr/local/lib64/python2.7/site-packages/django/core/urlresolvers.py", line 410, in url_patterns
    raise ImproperlyConfigured(msg.format(name=self.urlconf_name))
ImproperlyConfigured: The included urlconf 'None' does not appear to have any patterns in it. If you see valid patterns in the file then the issue is probably caused by a circular import.
[17/Mar/2017 12:34:00] ERROR [/usr/local/lib64/python2.7/site-packages/django/core/handlers/base.py:256] Internal Server Error: /
Traceback (most recent call last):
  File "/usr/local/lib64/python2.7/site-packages/django/core/handlers/base.py", line 164, in get_response
    response = response.render()
  File "/usr/local/lib64/python2.7/site-packages/django/template/response.py", line 158, in render
    self.content = self.rendered_content
  File "/usr/local/lib64/python2.7/site-packages/django/template/response.py", line 135, in rendered_content
    content = template.render(context, self._request)
  File "/usr/local/lib64/python2.7/site-packages/django/template/backends/django.py", line 74, in render
    return self.template.render(context)
  File "/usr/local/lib64/python2.7/site-packages/django/template/base.py", line 210, in render
    return self._render(context)
  File "/usr/local/lib64/python2.7/site-packages/django/template/base.py", line 202, in _render
    return self.nodelist.render(context)
  File "/usr/local/lib64/python2.7/site-packages/django/template/base.py", line 905, in render
    bit = self.render_node(node, context)
  File "/usr/local/lib64/python2.7/site-packages/django/template/base.py", line 919, in render_node
    return node.render(context)
  File "/usr/local/lib64/python2.7/site-packages/django/template/loader_tags.py", line 135, in render
    return compiled_parent._render(context)
  File "/usr/local/lib64/python2.7/site-packages/django/template/base.py", line 202, in _render
    return self.nodelist.render(context)
  File "/usr/local/lib64/python2.7/site-packages/django/template/base.py", line 905, in render
    bit = self.render_node(node, context)
  File "/usr/local/lib64/python2.7/site-packages/django/template/base.py", line 919, in render_node
    return node.render(context)
  File "/usr/local/lib64/python2.7/site-packages/django/template/loader_tags.py", line 65, in render
    result = block.nodelist.render(context)
  File "/usr/local/lib64/python2.7/site-packages/django/template/base.py", line 905, in render
    bit = self.render_node(node, context)
  File "/usr/local/lib64/python2.7/site-packages/django/template/base.py", line 919, in render_node
    return node.render(context)
  File "/usr/local/lib64/python2.7/site-packages/django/template/loader_tags.py", line 65, in render
    result = block.nodelist.render(context)
  File "/usr/local/lib64/python2.7/site-packages/django/template/base.py", line 905, in render
    bit = self.render_node(node, context)
  File "/usr/local/lib64/python2.7/site-packages/django/template/base.py", line 919, in render_node
    return node.render(context)
  File "/usr/local/lib64/python2.7/site-packages/django/template/loader_tags.py", line 65, in render
    result = block.nodelist.render(context)
  File "/usr/local/lib64/python2.7/site-packages/django/template/base.py", line 905, in render
    bit = self.render_node(node, context)
  File "/usr/local/lib64/python2.7/site-packages/django/template/base.py", line 919, in render_node
    return node.render(context)
  File "/usr/local/lib64/python2.7/site-packages/django/template/defaulttags.py", line 329, in render
    return nodelist.render(context)
  File "/usr/local/lib64/python2.7/site-packages/django/template/base.py", line 905, in render
    bit = self.render_node(node, context)
  File "/usr/local/lib64/python2.7/site-packages/django/template/base.py", line 919, in render_node
    return node.render(context)
  File "/usr/local/lib64/python2.7/site-packages/django/template/base.py", line 959, in render
    output = self.filter_expression.resolve(context)
  File "/usr/local/lib64/python2.7/site-packages/django/template/base.py", line 648, in resolve
    obj = self.var.resolve(context)
  File "/usr/local/lib64/python2.7/site-packages/django/template/base.py", line 789, in resolve
    value = self._resolve_lookup(context)
  File "/usr/local/lib64/python2.7/site-packages/django/template/base.py", line 849, in _resolve_lookup
    current = current()
  File "/usr/local/lib64/python2.7/site-packages/django/template/loader_tags.py", line 79, in super
    return mark_safe(self.render(self.context))
  File "/usr/local/lib64/python2.7/site-packages/django/template/loader_tags.py", line 65, in render
    result = block.nodelist.render(context)
  File "/usr/local/lib64/python2.7/site-packages/django/template/base.py", line 905, in render
    bit = self.render_node(node, context)
  File "/usr/local/lib64/python2.7/site-packages/django/template/base.py", line 919, in render_node
    return node.render(context)
  File "/usr/local/lib64/python2.7/site-packages/django/template/defaulttags.py", line 329, in render
    return nodelist.render(context)
  File "/usr/local/lib64/python2.7/site-packages/django/template/base.py", line 905, in render
    bit = self.render_node(node, context)
  File "/usr/local/lib64/python2.7/site-packages/django/template/base.py", line 919, in render_node
    return node.render(context)
  File "/usr/local/lib64/python2.7/site-packages/django/template/defaulttags.py", line 329, in render
    return nodelist.render(context)
  File "/usr/local/lib64/python2.7/site-packages/django/template/base.py", line 905, in render
    bit = self.render_node(node, context)
  File "/usr/local/lib64/python2.7/site-packages/django/template/base.py", line 919, in render_node
    return node.render(context)
  File "/usr/local/lib64/python2.7/site-packages/django/template/defaulttags.py", line 493, in render
    url = reverse(view_name, args=args, kwargs=kwargs, current_app=current_app)
  File "/usr/local/lib64/python2.7/site-packages/django/core/urlresolvers.py", line 578, in reverse
    return force_text(iri_to_uri(resolver._reverse_with_prefix(view, prefix, *args, **kwargs)))
  File "/usr/local/lib64/python2.7/site-packages/django/core/urlresolvers.py", line 432, in _reverse_with_prefix
    self._populate()
  File "/usr/local/lib64/python2.7/site-packages/django/core/urlresolvers.py", line 307, in _populate
    for name in pattern.reverse_dict:
  File "/usr/local/lib64/python2.7/site-packages/django/core/urlresolvers.py", line 337, in reverse_dict
    self._populate()
  File "/usr/local/lib64/python2.7/site-packages/django/core/urlresolvers.py", line 307, in _populate
    for name in pattern.reverse_dict:
  File "/usr/local/lib64/python2.7/site-packages/django/core/urlresolvers.py", line 337, in reverse_dict
    self._populate()
  File "/usr/local/lib64/python2.7/site-packages/django/core/urlresolvers.py", line 284, in _populate
    for pattern in reversed(self.url_patterns):
  File "/usr/local/lib64/python2.7/site-packages/django/core/urlresolvers.py", line 410, in url_patterns
    raise ImproperlyConfigured(msg.format(name=self.urlconf_name))
ImproperlyConfigured: The included urlconf 'None' does not appear to have any patterns in it. If you see valid patterns in the file then the issue is probably caused by a circular import.
[17/Mar/2017 12:43:03] ERROR [/usr/local/lib64/python2.7/site-packages/django/core/handlers/base.py:256] Internal Server Error: /
Traceback (most recent call last):
  File "/usr/local/lib64/python2.7/site-packages/django/core/handlers/base.py", line 164, in get_response
    response = response.render()
  File "/usr/local/lib64/python2.7/site-packages/django/template/response.py", line 158, in render
    self.content = self.rendered_content
  File "/usr/local/lib64/python2.7/site-packages/django/template/response.py", line 135, in rendered_content
    content = template.render(context, self._request)
  File "/usr/local/lib64/python2.7/site-packages/django/template/backends/django.py", line 74, in render
    return self.template.render(context)
  File "/usr/local/lib64/python2.7/site-packages/django/template/base.py", line 210, in render
    return self._render(context)
  File "/usr/local/lib64/python2.7/site-packages/django/template/base.py", line 202, in _render
    return self.nodelist.render(context)
  File "/usr/local/lib64/python2.7/site-packages/django/template/base.py", line 905, in render
    bit = self.render_node(node, context)
  File "/usr/local/lib64/python2.7/site-packages/django/template/base.py", line 919, in render_node
    return node.render(context)
  File "/usr/local/lib64/python2.7/site-packages/django/template/loader_tags.py", line 135, in render
    return compiled_parent._render(context)
  File "/usr/local/lib64/python2.7/site-packages/django/template/base.py", line 202, in _render
    return self.nodelist.render(context)
  File "/usr/local/lib64/python2.7/site-packages/django/template/base.py", line 905, in render
    bit = self.render_node(node, context)
  File "/usr/local/lib64/python2.7/site-packages/django/template/base.py", line 919, in render_node
    return node.render(context)
  File "/usr/local/lib64/python2.7/site-packages/django/template/loader_tags.py", line 65, in render
    result = block.nodelist.render(context)
  File "/usr/local/lib64/python2.7/site-packages/django/template/base.py", line 905, in render
    bit = self.render_node(node, context)
  File "/usr/local/lib64/python2.7/site-packages/django/template/base.py", line 919, in render_node
    return node.render(context)
  File "/usr/local/lib64/python2.7/site-packages/django/template/loader_tags.py", line 65, in render
    result = block.nodelist.render(context)
  File "/usr/local/lib64/python2.7/site-packages/django/template/base.py", line 905, in render
    bit = self.render_node(node, context)
  File "/usr/local/lib64/python2.7/site-packages/django/template/base.py", line 919, in render_node
    return node.render(context)
  File "/usr/local/lib64/python2.7/site-packages/django/template/loader_tags.py", line 65, in render
    result = block.nodelist.render(context)
  File "/usr/local/lib64/python2.7/site-packages/django/template/base.py", line 905, in render
    bit = self.render_node(node, context)
  File "/usr/local/lib64/python2.7/site-packages/django/template/base.py", line 919, in render_node
    return node.render(context)
  File "/usr/local/lib64/python2.7/site-packages/django/template/defaulttags.py", line 329, in render
    return nodelist.render(context)
  File "/usr/local/lib64/python2.7/site-packages/django/template/base.py", line 905, in render
    bit = self.render_node(node, context)
  File "/usr/local/lib64/python2.7/site-packages/django/template/base.py", line 919, in render_node
    return node.render(context)
  File "/usr/local/lib64/python2.7/site-packages/django/template/base.py", line 959, in render
    output = self.filter_expression.resolve(context)
  File "/usr/local/lib64/python2.7/site-packages/django/template/base.py", line 648, in resolve
    obj = self.var.resolve(context)
  File "/usr/local/lib64/python2.7/site-packages/django/template/base.py", line 789, in resolve
    value = self._resolve_lookup(context)
  File "/usr/local/lib64/python2.7/site-packages/django/template/base.py", line 849, in _resolve_lookup
    current = current()
  File "/usr/local/lib64/python2.7/site-packages/django/template/loader_tags.py", line 79, in super
    return mark_safe(self.render(self.context))
  File "/usr/local/lib64/python2.7/site-packages/django/template/loader_tags.py", line 65, in render
    result = block.nodelist.render(context)
  File "/usr/local/lib64/python2.7/site-packages/django/template/base.py", line 905, in render
    bit = self.render_node(node, context)
  File "/usr/local/lib64/python2.7/site-packages/django/template/base.py", line 919, in render_node
    return node.render(context)
  File "/usr/local/lib64/python2.7/site-packages/django/template/defaulttags.py", line 329, in render
    return nodelist.render(context)
  File "/usr/local/lib64/python2.7/site-packages/django/template/base.py", line 905, in render
    bit = self.render_node(node, context)
  File "/usr/local/lib64/python2.7/site-packages/django/template/base.py", line 919, in render_node
    return node.render(context)
  File "/usr/local/lib64/python2.7/site-packages/django/template/defaulttags.py", line 329, in render
    return nodelist.render(context)
  File "/usr/local/lib64/python2.7/site-packages/django/template/base.py", line 905, in render
    bit = self.render_node(node, context)
  File "/usr/local/lib64/python2.7/site-packages/django/template/base.py", line 919, in render_node
    return node.render(context)
  File "/usr/local/lib64/python2.7/site-packages/django/template/defaulttags.py", line 493, in render
    url = reverse(view_name, args=args, kwargs=kwargs, current_app=current_app)
  File "/usr/local/lib64/python2.7/site-packages/django/core/urlresolvers.py", line 578, in reverse
    return force_text(iri_to_uri(resolver._reverse_with_prefix(view, prefix, *args, **kwargs)))
  File "/usr/local/lib64/python2.7/site-packages/django/core/urlresolvers.py", line 432, in _reverse_with_prefix
    self._populate()
  File "/usr/local/lib64/python2.7/site-packages/django/core/urlresolvers.py", line 307, in _populate
    for name in pattern.reverse_dict:
  File "/usr/local/lib64/python2.7/site-packages/django/core/urlresolvers.py", line 337, in reverse_dict
    self._populate()
  File "/usr/local/lib64/python2.7/site-packages/django/core/urlresolvers.py", line 307, in _populate
    for name in pattern.reverse_dict:
  File "/usr/local/lib64/python2.7/site-packages/django/core/urlresolvers.py", line 337, in reverse_dict
    self._populate()
  File "/usr/local/lib64/python2.7/site-packages/django/core/urlresolvers.py", line 284, in _populate
    for pattern in reversed(self.url_patterns):
  File "/usr/local/lib64/python2.7/site-packages/django/core/urlresolvers.py", line 410, in url_patterns
    raise ImproperlyConfigured(msg.format(name=self.urlconf_name))
ImproperlyConfigured: The included urlconf 'None' does not appear to have any patterns in it. If you see valid patterns in the file then the issue is probably caused by a circular import.
[17/Mar/2017 12:43:10] ERROR [/usr/local/lib64/python2.7/site-packages/django/core/handlers/base.py:256] Internal Server Error: /
Traceback (most recent call last):
  File "/usr/local/lib64/python2.7/site-packages/django/core/handlers/base.py", line 164, in get_response
    response = response.render()
  File "/usr/local/lib64/python2.7/site-packages/django/template/response.py", line 158, in render
    self.content = self.rendered_content
  File "/usr/local/lib64/python2.7/site-packages/django/template/response.py", line 135, in rendered_content
    content = template.render(context, self._request)
  File "/usr/local/lib64/python2.7/site-packages/django/template/backends/django.py", line 74, in render
    return self.template.render(context)
  File "/usr/local/lib64/python2.7/site-packages/django/template/base.py", line 210, in render
    return self._render(context)
  File "/usr/local/lib64/python2.7/site-packages/django/template/base.py", line 202, in _render
    return self.nodelist.render(context)
  File "/usr/local/lib64/python2.7/site-packages/django/template/base.py", line 905, in render
    bit = self.render_node(node, context)
  File "/usr/local/lib64/python2.7/site-packages/django/template/base.py", line 919, in render_node
    return node.render(context)
  File "/usr/local/lib64/python2.7/site-packages/django/template/loader_tags.py", line 135, in render
    return compiled_parent._render(context)
  File "/usr/local/lib64/python2.7/site-packages/django/template/base.py", line 202, in _render
    return self.nodelist.render(context)
  File "/usr/local/lib64/python2.7/site-packages/django/template/base.py", line 905, in render
    bit = self.render_node(node, context)
  File "/usr/local/lib64/python2.7/site-packages/django/template/base.py", line 919, in render_node
    return node.render(context)
  File "/usr/local/lib64/python2.7/site-packages/django/template/loader_tags.py", line 65, in render
    result = block.nodelist.render(context)
  File "/usr/local/lib64/python2.7/site-packages/django/template/base.py", line 905, in render
    bit = self.render_node(node, context)
  File "/usr/local/lib64/python2.7/site-packages/django/template/base.py", line 919, in render_node
    return node.render(context)
  File "/usr/local/lib64/python2.7/site-packages/django/template/loader_tags.py", line 65, in render
    result = block.nodelist.render(context)
  File "/usr/local/lib64/python2.7/site-packages/django/template/base.py", line 905, in render
    bit = self.render_node(node, context)
  File "/usr/local/lib64/python2.7/site-packages/django/template/base.py", line 919, in render_node
    return node.render(context)
  File "/usr/local/lib64/python2.7/site-packages/django/template/loader_tags.py", line 65, in render
    result = block.nodelist.render(context)
  File "/usr/local/lib64/python2.7/site-packages/django/template/base.py", line 905, in render
    bit = self.render_node(node, context)
  File "/usr/local/lib64/python2.7/site-packages/django/template/base.py", line 919, in render_node
    return node.render(context)
  File "/usr/local/lib64/python2.7/site-packages/django/template/defaulttags.py", line 329, in render
    return nodelist.render(context)
  File "/usr/local/lib64/python2.7/site-packages/django/template/base.py", line 905, in render
    bit = self.render_node(node, context)
  File "/usr/local/lib64/python2.7/site-packages/django/template/base.py", line 919, in render_node
    return node.render(context)
  File "/usr/local/lib64/python2.7/site-packages/django/template/base.py", line 959, in render
    output = self.filter_expression.resolve(context)
  File "/usr/local/lib64/python2.7/site-packages/django/template/base.py", line 648, in resolve
    obj = self.var.resolve(context)
  File "/usr/local/lib64/python2.7/site-packages/django/template/base.py", line 789, in resolve
    value = self._resolve_lookup(context)
  File "/usr/local/lib64/python2.7/site-packages/django/template/base.py", line 849, in _resolve_lookup
    current = current()
  File "/usr/local/lib64/python2.7/site-packages/django/template/loader_tags.py", line 79, in super
    return mark_safe(self.render(self.context))
  File "/usr/local/lib64/python2.7/site-packages/django/template/loader_tags.py", line 65, in render
    result = block.nodelist.render(context)
  File "/usr/local/lib64/python2.7/site-packages/django/template/base.py", line 905, in render
    bit = self.render_node(node, context)
  File "/usr/local/lib64/python2.7/site-packages/django/template/base.py", line 919, in render_node
    return node.render(context)
  File "/usr/local/lib64/python2.7/site-packages/django/template/defaulttags.py", line 329, in render
    return nodelist.render(context)
  File "/usr/local/lib64/python2.7/site-packages/django/template/base.py", line 905, in render
    bit = self.render_node(node, context)
  File "/usr/local/lib64/python2.7/site-packages/django/template/base.py", line 919, in render_node
    return node.render(context)
  File "/usr/local/lib64/python2.7/site-packages/django/template/defaulttags.py", line 329, in render
    return nodelist.render(context)
  File "/usr/local/lib64/python2.7/site-packages/django/template/base.py", line 905, in render
    bit = self.render_node(node, context)
  File "/usr/local/lib64/python2.7/site-packages/django/template/base.py", line 919, in render_node
    return node.render(context)
  File "/usr/local/lib64/python2.7/site-packages/django/template/defaulttags.py", line 493, in render
    url = reverse(view_name, args=args, kwargs=kwargs, current_app=current_app)
  File "/usr/local/lib64/python2.7/site-packages/django/core/urlresolvers.py", line 578, in reverse
    return force_text(iri_to_uri(resolver._reverse_with_prefix(view, prefix, *args, **kwargs)))
  File "/usr/local/lib64/python2.7/site-packages/django/core/urlresolvers.py", line 432, in _reverse_with_prefix
    self._populate()
  File "/usr/local/lib64/python2.7/site-packages/django/core/urlresolvers.py", line 307, in _populate
    for name in pattern.reverse_dict:
  File "/usr/local/lib64/python2.7/site-packages/django/core/urlresolvers.py", line 337, in reverse_dict
    self._populate()
  File "/usr/local/lib64/python2.7/site-packages/django/core/urlresolvers.py", line 307, in _populate
    for name in pattern.reverse_dict:
  File "/usr/local/lib64/python2.7/site-packages/django/core/urlresolvers.py", line 337, in reverse_dict
    self._populate()
  File "/usr/local/lib64/python2.7/site-packages/django/core/urlresolvers.py", line 284, in _populate
    for pattern in reversed(self.url_patterns):
  File "/usr/local/lib64/python2.7/site-packages/django/core/urlresolvers.py", line 410, in url_patterns
    raise ImproperlyConfigured(msg.format(name=self.urlconf_name))
ImproperlyConfigured: The included urlconf 'None' does not appear to have any patterns in it. If you see valid patterns in the file then the issue is probably caused by a circular import.
[17/Mar/2017 12:43:11] ERROR [/usr/local/lib64/python2.7/site-packages/django/core/handlers/base.py:256] Internal Server Error: /
Traceback (most recent call last):
  File "/usr/local/lib64/python2.7/site-packages/django/core/handlers/base.py", line 164, in get_response
    response = response.render()
  File "/usr/local/lib64/python2.7/site-packages/django/template/response.py", line 158, in render
    self.content = self.rendered_content
  File "/usr/local/lib64/python2.7/site-packages/django/template/response.py", line 135, in rendered_content
    content = template.render(context, self._request)
  File "/usr/local/lib64/python2.7/site-packages/django/template/backends/django.py", line 74, in render
    return self.template.render(context)
  File "/usr/local/lib64/python2.7/site-packages/django/template/base.py", line 210, in render
    return self._render(context)
  File "/usr/local/lib64/python2.7/site-packages/django/template/base.py", line 202, in _render
    return self.nodelist.render(context)
  File "/usr/local/lib64/python2.7/site-packages/django/template/base.py", line 905, in render
    bit = self.render_node(node, context)
  File "/usr/local/lib64/python2.7/site-packages/django/template/base.py", line 919, in render_node
    return node.render(context)
  File "/usr/local/lib64/python2.7/site-packages/django/template/loader_tags.py", line 135, in render
    return compiled_parent._render(context)
  File "/usr/local/lib64/python2.7/site-packages/django/template/base.py", line 202, in _render
    return self.nodelist.render(context)
  File "/usr/local/lib64/python2.7/site-packages/django/template/base.py", line 905, in render
    bit = self.render_node(node, context)
  File "/usr/local/lib64/python2.7/site-packages/django/template/base.py", line 919, in render_node
    return node.render(context)
  File "/usr/local/lib64/python2.7/site-packages/django/template/loader_tags.py", line 65, in render
    result = block.nodelist.render(context)
  File "/usr/local/lib64/python2.7/site-packages/django/template/base.py", line 905, in render
    bit = self.render_node(node, context)
  File "/usr/local/lib64/python2.7/site-packages/django/template/base.py", line 919, in render_node
    return node.render(context)
  File "/usr/local/lib64/python2.7/site-packages/django/template/loader_tags.py", line 65, in render
    result = block.nodelist.render(context)
  File "/usr/local/lib64/python2.7/site-packages/django/template/base.py", line 905, in render
    bit = self.render_node(node, context)
  File "/usr/local/lib64/python2.7/site-packages/django/template/base.py", line 919, in render_node
    return node.render(context)
  File "/usr/local/lib64/python2.7/site-packages/django/template/loader_tags.py", line 65, in render
    result = block.nodelist.render(context)
  File "/usr/local/lib64/python2.7/site-packages/django/template/base.py", line 905, in render
    bit = self.render_node(node, context)
  File "/usr/local/lib64/python2.7/site-packages/django/template/base.py", line 919, in render_node
    return node.render(context)
  File "/usr/local/lib64/python2.7/site-packages/django/template/defaulttags.py", line 329, in render
    return nodelist.render(context)
  File "/usr/local/lib64/python2.7/site-packages/django/template/base.py", line 905, in render
    bit = self.render_node(node, context)
  File "/usr/local/lib64/python2.7/site-packages/django/template/base.py", line 919, in render_node
    return node.render(context)
  File "/usr/local/lib64/python2.7/site-packages/django/template/base.py", line 959, in render
    output = self.filter_expression.resolve(context)
  File "/usr/local/lib64/python2.7/site-packages/django/template/base.py", line 648, in resolve
    obj = self.var.resolve(context)
  File "/usr/local/lib64/python2.7/site-packages/django/template/base.py", line 789, in resolve
    value = self._resolve_lookup(context)
  File "/usr/local/lib64/python2.7/site-packages/django/template/base.py", line 849, in _resolve_lookup
    current = current()
  File "/usr/local/lib64/python2.7/site-packages/django/template/loader_tags.py", line 79, in super
    return mark_safe(self.render(self.context))
  File "/usr/local/lib64/python2.7/site-packages/django/template/loader_tags.py", line 65, in render
    result = block.nodelist.render(context)
  File "/usr/local/lib64/python2.7/site-packages/django/template/base.py", line 905, in render
    bit = self.render_node(node, context)
  File "/usr/local/lib64/python2.7/site-packages/django/template/base.py", line 919, in render_node
    return node.render(context)
  File "/usr/local/lib64/python2.7/site-packages/django/template/defaulttags.py", line 329, in render
    return nodelist.render(context)
  File "/usr/local/lib64/python2.7/site-packages/django/template/base.py", line 905, in render
    bit = self.render_node(node, context)
  File "/usr/local/lib64/python2.7/site-packages/django/template/base.py", line 919, in render_node
    return node.render(context)
  File "/usr/local/lib64/python2.7/site-packages/django/template/defaulttags.py", line 329, in render
    return nodelist.render(context)
  File "/usr/local/lib64/python2.7/site-packages/django/template/base.py", line 905, in render
    bit = self.render_node(node, context)
  File "/usr/local/lib64/python2.7/site-packages/django/template/base.py", line 919, in render_node
    return node.render(context)
  File "/usr/local/lib64/python2.7/site-packages/django/template/defaulttags.py", line 493, in render
    url = reverse(view_name, args=args, kwargs=kwargs, current_app=current_app)
  File "/usr/local/lib64/python2.7/site-packages/django/core/urlresolvers.py", line 578, in reverse
    return force_text(iri_to_uri(resolver._reverse_with_prefix(view, prefix, *args, **kwargs)))
  File "/usr/local/lib64/python2.7/site-packages/django/core/urlresolvers.py", line 432, in _reverse_with_prefix
    self._populate()
  File "/usr/local/lib64/python2.7/site-packages/django/core/urlresolvers.py", line 307, in _populate
    for name in pattern.reverse_dict:
  File "/usr/local/lib64/python2.7/site-packages/django/core/urlresolvers.py", line 337, in reverse_dict
    self._populate()
  File "/usr/local/lib64/python2.7/site-packages/django/core/urlresolvers.py", line 307, in _populate
    for name in pattern.reverse_dict:
  File "/usr/local/lib64/python2.7/site-packages/django/core/urlresolvers.py", line 337, in reverse_dict
    self._populate()
  File "/usr/local/lib64/python2.7/site-packages/django/core/urlresolvers.py", line 284, in _populate
    for pattern in reversed(self.url_patterns):
  File "/usr/local/lib64/python2.7/site-packages/django/core/urlresolvers.py", line 410, in url_patterns
    raise ImproperlyConfigured(msg.format(name=self.urlconf_name))
ImproperlyConfigured: The included urlconf 'None' does not appear to have any patterns in it. If you see valid patterns in the file then the issue is probably caused by a circular import.
[17/Mar/2017 12:43:12] ERROR [/usr/local/lib64/python2.7/site-packages/django/core/handlers/base.py:256] Internal Server Error: /
Traceback (most recent call last):
  File "/usr/local/lib64/python2.7/site-packages/django/core/handlers/base.py", line 164, in get_response
    response = response.render()
  File "/usr/local/lib64/python2.7/site-packages/django/template/response.py", line 158, in render
    self.content = self.rendered_content
  File "/usr/local/lib64/python2.7/site-packages/django/template/response.py", line 135, in rendered_content
    content = template.render(context, self._request)
  File "/usr/local/lib64/python2.7/site-packages/django/template/backends/django.py", line 74, in render
    return self.template.render(context)
  File "/usr/local/lib64/python2.7/site-packages/django/template/base.py", line 210, in render
    return self._render(context)
  File "/usr/local/lib64/python2.7/site-packages/django/template/base.py", line 202, in _render
    return self.nodelist.render(context)
  File "/usr/local/lib64/python2.7/site-packages/django/template/base.py", line 905, in render
    bit = self.render_node(node, context)
  File "/usr/local/lib64/python2.7/site-packages/django/template/base.py", line 919, in render_node
    return node.render(context)
  File "/usr/local/lib64/python2.7/site-packages/django/template/loader_tags.py", line 135, in render
    return compiled_parent._render(context)
  File "/usr/local/lib64/python2.7/site-packages/django/template/base.py", line 202, in _render
    return self.nodelist.render(context)
  File "/usr/local/lib64/python2.7/site-packages/django/template/base.py", line 905, in render
    bit = self.render_node(node, context)
  File "/usr/local/lib64/python2.7/site-packages/django/template/base.py", line 919, in render_node
    return node.render(context)
  File "/usr/local/lib64/python2.7/site-packages/django/template/loader_tags.py", line 65, in render
    result = block.nodelist.render(context)
  File "/usr/local/lib64/python2.7/site-packages/django/template/base.py", line 905, in render
    bit = self.render_node(node, context)
  File "/usr/local/lib64/python2.7/site-packages/django/template/base.py", line 919, in render_node
    return node.render(context)
  File "/usr/local/lib64/python2.7/site-packages/django/template/loader_tags.py", line 65, in render
    result = block.nodelist.render(context)
  File "/usr/local/lib64/python2.7/site-packages/django/template/base.py", line 905, in render
    bit = self.render_node(node, context)
  File "/usr/local/lib64/python2.7/site-packages/django/template/base.py", line 919, in render_node
    return node.render(context)
  File "/usr/local/lib64/python2.7/site-packages/django/template/loader_tags.py", line 65, in render
    result = block.nodelist.render(context)
  File "/usr/local/lib64/python2.7/site-packages/django/template/base.py", line 905, in render
    bit = self.render_node(node, context)
  File "/usr/local/lib64/python2.7/site-packages/django/template/base.py", line 919, in render_node
    return node.render(context)
  File "/usr/local/lib64/python2.7/site-packages/django/template/defaulttags.py", line 329, in render
    return nodelist.render(context)
  File "/usr/local/lib64/python2.7/site-packages/django/template/base.py", line 905, in render
    bit = self.render_node(node, context)
  File "/usr/local/lib64/python2.7/site-packages/django/template/base.py", line 919, in render_node
    return node.render(context)
  File "/usr/local/lib64/python2.7/site-packages/django/template/base.py", line 959, in render
    output = self.filter_expression.resolve(context)
  File "/usr/local/lib64/python2.7/site-packages/django/template/base.py", line 648, in resolve
    obj = self.var.resolve(context)
  File "/usr/local/lib64/python2.7/site-packages/django/template/base.py", line 789, in resolve
    value = self._resolve_lookup(context)
  File "/usr/local/lib64/python2.7/site-packages/django/template/base.py", line 849, in _resolve_lookup
    current = current()
  File "/usr/local/lib64/python2.7/site-packages/django/template/loader_tags.py", line 79, in super
    return mark_safe(self.render(self.context))
  File "/usr/local/lib64/python2.7/site-packages/django/template/loader_tags.py", line 65, in render
    result = block.nodelist.render(context)
  File "/usr/local/lib64/python2.7/site-packages/django/template/base.py", line 905, in render
    bit = self.render_node(node, context)
  File "/usr/local/lib64/python2.7/site-packages/django/template/base.py", line 919, in render_node
    return node.render(context)
  File "/usr/local/lib64/python2.7/site-packages/django/template/defaulttags.py", line 329, in render
    return nodelist.render(context)
  File "/usr/local/lib64/python2.7/site-packages/django/template/base.py", line 905, in render
    bit = self.render_node(node, context)
  File "/usr/local/lib64/python2.7/site-packages/django/template/base.py", line 919, in render_node
    return node.render(context)
  File "/usr/local/lib64/python2.7/site-packages/django/template/defaulttags.py", line 329, in render
    return nodelist.render(context)
  File "/usr/local/lib64/python2.7/site-packages/django/template/base.py", line 905, in render
    bit = self.render_node(node, context)
  File "/usr/local/lib64/python2.7/site-packages/django/template/base.py", line 919, in render_node
    return node.render(context)
  File "/usr/local/lib64/python2.7/site-packages/django/template/defaulttags.py", line 493, in render
    url = reverse(view_name, args=args, kwargs=kwargs, current_app=current_app)
  File "/usr/local/lib64/python2.7/site-packages/django/core/urlresolvers.py", line 578, in reverse
    return force_text(iri_to_uri(resolver._reverse_with_prefix(view, prefix, *args, **kwargs)))
  File "/usr/local/lib64/python2.7/site-packages/django/core/urlresolvers.py", line 432, in _reverse_with_prefix
    self._populate()
  File "/usr/local/lib64/python2.7/site-packages/django/core/urlresolvers.py", line 307, in _populate
    for name in pattern.reverse_dict:
  File "/usr/local/lib64/python2.7/site-packages/django/core/urlresolvers.py", line 337, in reverse_dict
    self._populate()
  File "/usr/local/lib64/python2.7/site-packages/django/core/urlresolvers.py", line 307, in _populate
    for name in pattern.reverse_dict:
  File "/usr/local/lib64/python2.7/site-packages/django/core/urlresolvers.py", line 337, in reverse_dict
    self._populate()
  File "/usr/local/lib64/python2.7/site-packages/django/core/urlresolvers.py", line 284, in _populate
    for pattern in reversed(self.url_patterns):
  File "/usr/local/lib64/python2.7/site-packages/django/core/urlresolvers.py", line 410, in url_patterns
    raise ImproperlyConfigured(msg.format(name=self.urlconf_name))
ImproperlyConfigured: The included urlconf 'None' does not appear to have any patterns in it. If you see valid patterns in the file then the issue is probably caused by a circular import.
[17/Mar/2017 12:43:14] ERROR [/usr/local/lib64/python2.7/site-packages/django/core/handlers/base.py:256] Internal Server Error: /
Traceback (most recent call last):
  File "/usr/local/lib64/python2.7/site-packages/django/core/handlers/base.py", line 164, in get_response
    response = response.render()
  File "/usr/local/lib64/python2.7/site-packages/django/template/response.py", line 158, in render
    self.content = self.rendered_content
  File "/usr/local/lib64/python2.7/site-packages/django/template/response.py", line 135, in rendered_content
    content = template.render(context, self._request)
  File "/usr/local/lib64/python2.7/site-packages/django/template/backends/django.py", line 74, in render
    return self.template.render(context)
  File "/usr/local/lib64/python2.7/site-packages/django/template/base.py", line 210, in render
    return self._render(context)
  File "/usr/local/lib64/python2.7/site-packages/django/template/base.py", line 202, in _render
    return self.nodelist.render(context)
  File "/usr/local/lib64/python2.7/site-packages/django/template/base.py", line 905, in render
    bit = self.render_node(node, context)
  File "/usr/local/lib64/python2.7/site-packages/django/template/base.py", line 919, in render_node
    return node.render(context)
  File "/usr/local/lib64/python2.7/site-packages/django/template/loader_tags.py", line 135, in render
    return compiled_parent._render(context)
  File "/usr/local/lib64/python2.7/site-packages/django/template/base.py", line 202, in _render
    return self.nodelist.render(context)
  File "/usr/local/lib64/python2.7/site-packages/django/template/base.py", line 905, in render
    bit = self.render_node(node, context)
  File "/usr/local/lib64/python2.7/site-packages/django/template/base.py", line 919, in render_node
    return node.render(context)
  File "/usr/local/lib64/python2.7/site-packages/django/template/loader_tags.py", line 65, in render
    result = block.nodelist.render(context)
  File "/usr/local/lib64/python2.7/site-packages/django/template/base.py", line 905, in render
    bit = self.render_node(node, context)
  File "/usr/local/lib64/python2.7/site-packages/django/template/base.py", line 919, in render_node
    return node.render(context)
  File "/usr/local/lib64/python2.7/site-packages/django/template/loader_tags.py", line 65, in render
    result = block.nodelist.render(context)
  File "/usr/local/lib64/python2.7/site-packages/django/template/base.py", line 905, in render
    bit = self.render_node(node, context)
  File "/usr/local/lib64/python2.7/site-packages/django/template/base.py", line 919, in render_node
    return node.render(context)
  File "/usr/local/lib64/python2.7/site-packages/django/template/loader_tags.py", line 65, in render
    result = block.nodelist.render(context)
  File "/usr/local/lib64/python2.7/site-packages/django/template/base.py", line 905, in render
    bit = self.render_node(node, context)
  File "/usr/local/lib64/python2.7/site-packages/django/template/base.py", line 919, in render_node
    return node.render(context)
  File "/usr/local/lib64/python2.7/site-packages/django/template/defaulttags.py", line 329, in render
    return nodelist.render(context)
  File "/usr/local/lib64/python2.7/site-packages/django/template/base.py", line 905, in render
    bit = self.render_node(node, context)
  File "/usr/local/lib64/python2.7/site-packages/django/template/base.py", line 919, in render_node
    return node.render(context)
  File "/usr/local/lib64/python2.7/site-packages/django/template/base.py", line 959, in render
    output = self.filter_expression.resolve(context)
  File "/usr/local/lib64/python2.7/site-packages/django/template/base.py", line 648, in resolve
    obj = self.var.resolve(context)
  File "/usr/local/lib64/python2.7/site-packages/django/template/base.py", line 789, in resolve
    value = self._resolve_lookup(context)
  File "/usr/local/lib64/python2.7/site-packages/django/template/base.py", line 849, in _resolve_lookup
    current = current()
  File "/usr/local/lib64/python2.7/site-packages/django/template/loader_tags.py", line 79, in super
    return mark_safe(self.render(self.context))
  File "/usr/local/lib64/python2.7/site-packages/django/template/loader_tags.py", line 65, in render
    result = block.nodelist.render(context)
  File "/usr/local/lib64/python2.7/site-packages/django/template/base.py", line 905, in render
    bit = self.render_node(node, context)
  File "/usr/local/lib64/python2.7/site-packages/django/template/base.py", line 919, in render_node
    return node.render(context)
  File "/usr/local/lib64/python2.7/site-packages/django/template/defaulttags.py", line 329, in render
    return nodelist.render(context)
  File "/usr/local/lib64/python2.7/site-packages/django/template/base.py", line 905, in render
    bit = self.render_node(node, context)
  File "/usr/local/lib64/python2.7/site-packages/django/template/base.py", line 919, in render_node
    return node.render(context)
  File "/usr/local/lib64/python2.7/site-packages/django/template/defaulttags.py", line 329, in render
    return nodelist.render(context)
  File "/usr/local/lib64/python2.7/site-packages/django/template/base.py", line 905, in render
    bit = self.render_node(node, context)
  File "/usr/local/lib64/python2.7/site-packages/django/template/base.py", line 919, in render_node
    return node.render(context)
  File "/usr/local/lib64/python2.7/site-packages/django/template/defaulttags.py", line 493, in render
    url = reverse(view_name, args=args, kwargs=kwargs, current_app=current_app)
  File "/usr/local/lib64/python2.7/site-packages/django/core/urlresolvers.py", line 578, in reverse
    return force_text(iri_to_uri(resolver._reverse_with_prefix(view, prefix, *args, **kwargs)))
  File "/usr/local/lib64/python2.7/site-packages/django/core/urlresolvers.py", line 432, in _reverse_with_prefix
    self._populate()
  File "/usr/local/lib64/python2.7/site-packages/django/core/urlresolvers.py", line 307, in _populate
    for name in pattern.reverse_dict:
  File "/usr/local/lib64/python2.7/site-packages/django/core/urlresolvers.py", line 337, in reverse_dict
    self._populate()
  File "/usr/local/lib64/python2.7/site-packages/django/core/urlresolvers.py", line 307, in _populate
    for name in pattern.reverse_dict:
  File "/usr/local/lib64/python2.7/site-packages/django/core/urlresolvers.py", line 337, in reverse_dict
    self._populate()
  File "/usr/local/lib64/python2.7/site-packages/django/core/urlresolvers.py", line 284, in _populate
    for pattern in reversed(self.url_patterns):
  File "/usr/local/lib64/python2.7/site-packages/django/core/urlresolvers.py", line 410, in url_patterns
    raise ImproperlyConfigured(msg.format(name=self.urlconf_name))
ImproperlyConfigured: The included urlconf 'None' does not appear to have any patterns in it. If you see valid patterns in the file then the issue is probably caused by a circular import.
[17/Mar/2017 12:44:27] ERROR [/usr/local/lib64/python2.7/site-packages/django/core/handlers/base.py:256] Internal Server Error: /
Traceback (most recent call last):
  File "/usr/local/lib64/python2.7/site-packages/django/core/handlers/base.py", line 164, in get_response
    response = response.render()
  File "/usr/local/lib64/python2.7/site-packages/django/template/response.py", line 158, in render
    self.content = self.rendered_content
  File "/usr/local/lib64/python2.7/site-packages/django/template/response.py", line 135, in rendered_content
    content = template.render(context, self._request)
  File "/usr/local/lib64/python2.7/site-packages/django/template/backends/django.py", line 74, in render
    return self.template.render(context)
  File "/usr/local/lib64/python2.7/site-packages/django/template/base.py", line 210, in render
    return self._render(context)
  File "/usr/local/lib64/python2.7/site-packages/django/template/base.py", line 202, in _render
    return self.nodelist.render(context)
  File "/usr/local/lib64/python2.7/site-packages/django/template/base.py", line 905, in render
    bit = self.render_node(node, context)
  File "/usr/local/lib64/python2.7/site-packages/django/template/base.py", line 919, in render_node
    return node.render(context)
  File "/usr/local/lib64/python2.7/site-packages/django/template/loader_tags.py", line 135, in render
    return compiled_parent._render(context)
  File "/usr/local/lib64/python2.7/site-packages/django/template/base.py", line 202, in _render
    return self.nodelist.render(context)
  File "/usr/local/lib64/python2.7/site-packages/django/template/base.py", line 905, in render
    bit = self.render_node(node, context)
  File "/usr/local/lib64/python2.7/site-packages/django/template/base.py", line 919, in render_node
    return node.render(context)
  File "/usr/local/lib64/python2.7/site-packages/django/template/loader_tags.py", line 65, in render
    result = block.nodelist.render(context)
  File "/usr/local/lib64/python2.7/site-packages/django/template/base.py", line 905, in render
    bit = self.render_node(node, context)
  File "/usr/local/lib64/python2.7/site-packages/django/template/base.py", line 919, in render_node
    return node.render(context)
  File "/usr/local/lib64/python2.7/site-packages/django/template/loader_tags.py", line 65, in render
    result = block.nodelist.render(context)
  File "/usr/local/lib64/python2.7/site-packages/django/template/base.py", line 905, in render
    bit = self.render_node(node, context)
  File "/usr/local/lib64/python2.7/site-packages/django/template/base.py", line 919, in render_node
    return node.render(context)
  File "/usr/local/lib64/python2.7/site-packages/django/template/loader_tags.py", line 65, in render
    result = block.nodelist.render(context)
  File "/usr/local/lib64/python2.7/site-packages/django/template/base.py", line 905, in render
    bit = self.render_node(node, context)
  File "/usr/local/lib64/python2.7/site-packages/django/template/base.py", line 919, in render_node
    return node.render(context)
  File "/usr/local/lib64/python2.7/site-packages/django/template/defaulttags.py", line 329, in render
    return nodelist.render(context)
  File "/usr/local/lib64/python2.7/site-packages/django/template/base.py", line 905, in render
    bit = self.render_node(node, context)
  File "/usr/local/lib64/python2.7/site-packages/django/template/base.py", line 919, in render_node
    return node.render(context)
  File "/usr/local/lib64/python2.7/site-packages/django/template/base.py", line 959, in render
    output = self.filter_expression.resolve(context)
  File "/usr/local/lib64/python2.7/site-packages/django/template/base.py", line 648, in resolve
    obj = self.var.resolve(context)
  File "/usr/local/lib64/python2.7/site-packages/django/template/base.py", line 789, in resolve
    value = self._resolve_lookup(context)
  File "/usr/local/lib64/python2.7/site-packages/django/template/base.py", line 849, in _resolve_lookup
    current = current()
  File "/usr/local/lib64/python2.7/site-packages/django/template/loader_tags.py", line 79, in super
    return mark_safe(self.render(self.context))
  File "/usr/local/lib64/python2.7/site-packages/django/template/loader_tags.py", line 65, in render
    result = block.nodelist.render(context)
  File "/usr/local/lib64/python2.7/site-packages/django/template/base.py", line 905, in render
    bit = self.render_node(node, context)
  File "/usr/local/lib64/python2.7/site-packages/django/template/base.py", line 919, in render_node
    return node.render(context)
  File "/usr/local/lib64/python2.7/site-packages/django/template/defaulttags.py", line 329, in render
    return nodelist.render(context)
  File "/usr/local/lib64/python2.7/site-packages/django/template/base.py", line 905, in render
    bit = self.render_node(node, context)
  File "/usr/local/lib64/python2.7/site-packages/django/template/base.py", line 919, in render_node
    return node.render(context)
  File "/usr/local/lib64/python2.7/site-packages/django/template/defaulttags.py", line 329, in render
    return nodelist.render(context)
  File "/usr/local/lib64/python2.7/site-packages/django/template/base.py", line 905, in render
    bit = self.render_node(node, context)
  File "/usr/local/lib64/python2.7/site-packages/django/template/base.py", line 919, in render_node
    return node.render(context)
  File "/usr/local/lib64/python2.7/site-packages/django/template/defaulttags.py", line 493, in render
    url = reverse(view_name, args=args, kwargs=kwargs, current_app=current_app)
  File "/usr/local/lib64/python2.7/site-packages/django/core/urlresolvers.py", line 578, in reverse
    return force_text(iri_to_uri(resolver._reverse_with_prefix(view, prefix, *args, **kwargs)))
  File "/usr/local/lib64/python2.7/site-packages/django/core/urlresolvers.py", line 432, in _reverse_with_prefix
    self._populate()
  File "/usr/local/lib64/python2.7/site-packages/django/core/urlresolvers.py", line 307, in _populate
    for name in pattern.reverse_dict:
  File "/usr/local/lib64/python2.7/site-packages/django/core/urlresolvers.py", line 337, in reverse_dict
    self._populate()
  File "/usr/local/lib64/python2.7/site-packages/django/core/urlresolvers.py", line 307, in _populate
    for name in pattern.reverse_dict:
  File "/usr/local/lib64/python2.7/site-packages/django/core/urlresolvers.py", line 337, in reverse_dict
    self._populate()
  File "/usr/local/lib64/python2.7/site-packages/django/core/urlresolvers.py", line 284, in _populate
    for pattern in reversed(self.url_patterns):
  File "/usr/local/lib64/python2.7/site-packages/django/core/urlresolvers.py", line 410, in url_patterns
    raise ImproperlyConfigured(msg.format(name=self.urlconf_name))
ImproperlyConfigured: The included urlconf 'None' does not appear to have any patterns in it. If you see valid patterns in the file then the issue is probably caused by a circular import.
[17/Mar/2017 12:44:42] ERROR [/usr/local/lib64/python2.7/site-packages/django/core/handlers/base.py:256] Internal Server Error: /
Traceback (most recent call last):
  File "/usr/local/lib64/python2.7/site-packages/django/core/handlers/base.py", line 164, in get_response
    response = response.render()
  File "/usr/local/lib64/python2.7/site-packages/django/template/response.py", line 158, in render
    self.content = self.rendered_content
  File "/usr/local/lib64/python2.7/site-packages/django/template/response.py", line 135, in rendered_content
    content = template.render(context, self._request)
  File "/usr/local/lib64/python2.7/site-packages/django/template/backends/django.py", line 74, in render
    return self.template.render(context)
  File "/usr/local/lib64/python2.7/site-packages/django/template/base.py", line 210, in render
    return self._render(context)
  File "/usr/local/lib64/python2.7/site-packages/django/template/base.py", line 202, in _render
    return self.nodelist.render(context)
  File "/usr/local/lib64/python2.7/site-packages/django/template/base.py", line 905, in render
    bit = self.render_node(node, context)
  File "/usr/local/lib64/python2.7/site-packages/django/template/base.py", line 919, in render_node
    return node.render(context)
  File "/usr/local/lib64/python2.7/site-packages/django/template/loader_tags.py", line 135, in render
    return compiled_parent._render(context)
  File "/usr/local/lib64/python2.7/site-packages/django/template/base.py", line 202, in _render
    return self.nodelist.render(context)
  File "/usr/local/lib64/python2.7/site-packages/django/template/base.py", line 905, in render
    bit = self.render_node(node, context)
  File "/usr/local/lib64/python2.7/site-packages/django/template/base.py", line 919, in render_node
    return node.render(context)
  File "/usr/local/lib64/python2.7/site-packages/django/template/loader_tags.py", line 65, in render
    result = block.nodelist.render(context)
  File "/usr/local/lib64/python2.7/site-packages/django/template/base.py", line 905, in render
    bit = self.render_node(node, context)
  File "/usr/local/lib64/python2.7/site-packages/django/template/base.py", line 919, in render_node
    return node.render(context)
  File "/usr/local/lib64/python2.7/site-packages/django/template/loader_tags.py", line 65, in render
    result = block.nodelist.render(context)
  File "/usr/local/lib64/python2.7/site-packages/django/template/base.py", line 905, in render
    bit = self.render_node(node, context)
  File "/usr/local/lib64/python2.7/site-packages/django/template/base.py", line 919, in render_node
    return node.render(context)
  File "/usr/local/lib64/python2.7/site-packages/django/template/loader_tags.py", line 65, in render
    result = block.nodelist.render(context)
  File "/usr/local/lib64/python2.7/site-packages/django/template/base.py", line 905, in render
    bit = self.render_node(node, context)
  File "/usr/local/lib64/python2.7/site-packages/django/template/base.py", line 919, in render_node
    return node.render(context)
  File "/usr/local/lib64/python2.7/site-packages/django/template/defaulttags.py", line 329, in render
    return nodelist.render(context)
  File "/usr/local/lib64/python2.7/site-packages/django/template/base.py", line 905, in render
    bit = self.render_node(node, context)
  File "/usr/local/lib64/python2.7/site-packages/django/template/base.py", line 919, in render_node
    return node.render(context)
  File "/usr/local/lib64/python2.7/site-packages/django/template/base.py", line 959, in render
    output = self.filter_expression.resolve(context)
  File "/usr/local/lib64/python2.7/site-packages/django/template/base.py", line 648, in resolve
    obj = self.var.resolve(context)
  File "/usr/local/lib64/python2.7/site-packages/django/template/base.py", line 789, in resolve
    value = self._resolve_lookup(context)
  File "/usr/local/lib64/python2.7/site-packages/django/template/base.py", line 849, in _resolve_lookup
    current = current()
  File "/usr/local/lib64/python2.7/site-packages/django/template/loader_tags.py", line 79, in super
    return mark_safe(self.render(self.context))
  File "/usr/local/lib64/python2.7/site-packages/django/template/loader_tags.py", line 65, in render
    result = block.nodelist.render(context)
  File "/usr/local/lib64/python2.7/site-packages/django/template/base.py", line 905, in render
    bit = self.render_node(node, context)
  File "/usr/local/lib64/python2.7/site-packages/django/template/base.py", line 919, in render_node
    return node.render(context)
  File "/usr/local/lib64/python2.7/site-packages/django/template/defaulttags.py", line 329, in render
    return nodelist.render(context)
  File "/usr/local/lib64/python2.7/site-packages/django/template/base.py", line 905, in render
    bit = self.render_node(node, context)
  File "/usr/local/lib64/python2.7/site-packages/django/template/base.py", line 919, in render_node
    return node.render(context)
  File "/usr/local/lib64/python2.7/site-packages/django/template/defaulttags.py", line 329, in render
    return nodelist.render(context)
  File "/usr/local/lib64/python2.7/site-packages/django/template/base.py", line 905, in render
    bit = self.render_node(node, context)
  File "/usr/local/lib64/python2.7/site-packages/django/template/base.py", line 919, in render_node
    return node.render(context)
  File "/usr/local/lib64/python2.7/site-packages/django/template/defaulttags.py", line 493, in render
    url = reverse(view_name, args=args, kwargs=kwargs, current_app=current_app)
  File "/usr/local/lib64/python2.7/site-packages/django/core/urlresolvers.py", line 578, in reverse
    return force_text(iri_to_uri(resolver._reverse_with_prefix(view, prefix, *args, **kwargs)))
  File "/usr/local/lib64/python2.7/site-packages/django/core/urlresolvers.py", line 432, in _reverse_with_prefix
    self._populate()
  File "/usr/local/lib64/python2.7/site-packages/django/core/urlresolvers.py", line 307, in _populate
    for name in pattern.reverse_dict:
  File "/usr/local/lib64/python2.7/site-packages/django/core/urlresolvers.py", line 337, in reverse_dict
    self._populate()
  File "/usr/local/lib64/python2.7/site-packages/django/core/urlresolvers.py", line 307, in _populate
    for name in pattern.reverse_dict:
  File "/usr/local/lib64/python2.7/site-packages/django/core/urlresolvers.py", line 337, in reverse_dict
    self._populate()
  File "/usr/local/lib64/python2.7/site-packages/django/core/urlresolvers.py", line 284, in _populate
    for pattern in reversed(self.url_patterns):
  File "/usr/local/lib64/python2.7/site-packages/django/core/urlresolvers.py", line 410, in url_patterns
    raise ImproperlyConfigured(msg.format(name=self.urlconf_name))
ImproperlyConfigured: The included urlconf 'None' does not appear to have any patterns in it. If you see valid patterns in the file then the issue is probably caused by a circular import.
[17/Mar/2017 12:46:08] ERROR [/usr/local/lib64/python2.7/site-packages/django/core/handlers/base.py:256] Internal Server Error: /
Traceback (most recent call last):
  File "/usr/local/lib64/python2.7/site-packages/django/core/handlers/base.py", line 164, in get_response
    response = response.render()
  File "/usr/local/lib64/python2.7/site-packages/django/template/response.py", line 158, in render
    self.content = self.rendered_content
  File "/usr/local/lib64/python2.7/site-packages/django/template/response.py", line 135, in rendered_content
    content = template.render(context, self._request)
  File "/usr/local/lib64/python2.7/site-packages/django/template/backends/django.py", line 74, in render
    return self.template.render(context)
  File "/usr/local/lib64/python2.7/site-packages/django/template/base.py", line 210, in render
    return self._render(context)
  File "/usr/local/lib64/python2.7/site-packages/django/template/base.py", line 202, in _render
    return self.nodelist.render(context)
  File "/usr/local/lib64/python2.7/site-packages/django/template/base.py", line 905, in render
    bit = self.render_node(node, context)
  File "/usr/local/lib64/python2.7/site-packages/django/template/base.py", line 919, in render_node
    return node.render(context)
  File "/usr/local/lib64/python2.7/site-packages/django/template/loader_tags.py", line 135, in render
    return compiled_parent._render(context)
  File "/usr/local/lib64/python2.7/site-packages/django/template/base.py", line 202, in _render
    return self.nodelist.render(context)
  File "/usr/local/lib64/python2.7/site-packages/django/template/base.py", line 905, in render
    bit = self.render_node(node, context)
  File "/usr/local/lib64/python2.7/site-packages/django/template/base.py", line 919, in render_node
    return node.render(context)
  File "/usr/local/lib64/python2.7/site-packages/django/template/loader_tags.py", line 65, in render
    result = block.nodelist.render(context)
  File "/usr/local/lib64/python2.7/site-packages/django/template/base.py", line 905, in render
    bit = self.render_node(node, context)
  File "/usr/local/lib64/python2.7/site-packages/django/template/base.py", line 919, in render_node
    return node.render(context)
  File "/usr/local/lib64/python2.7/site-packages/django/template/loader_tags.py", line 65, in render
    result = block.nodelist.render(context)
  File "/usr/local/lib64/python2.7/site-packages/django/template/base.py", line 905, in render
    bit = self.render_node(node, context)
  File "/usr/local/lib64/python2.7/site-packages/django/template/base.py", line 919, in render_node
    return node.render(context)
  File "/usr/local/lib64/python2.7/site-packages/django/template/loader_tags.py", line 65, in render
    result = block.nodelist.render(context)
  File "/usr/local/lib64/python2.7/site-packages/django/template/base.py", line 905, in render
    bit = self.render_node(node, context)
  File "/usr/local/lib64/python2.7/site-packages/django/template/base.py", line 919, in render_node
    return node.render(context)
  File "/usr/local/lib64/python2.7/site-packages/django/template/defaulttags.py", line 329, in render
    return nodelist.render(context)
  File "/usr/local/lib64/python2.7/site-packages/django/template/base.py", line 905, in render
    bit = self.render_node(node, context)
  File "/usr/local/lib64/python2.7/site-packages/django/template/base.py", line 919, in render_node
    return node.render(context)
  File "/usr/local/lib64/python2.7/site-packages/django/template/base.py", line 959, in render
    output = self.filter_expression.resolve(context)
  File "/usr/local/lib64/python2.7/site-packages/django/template/base.py", line 648, in resolve
    obj = self.var.resolve(context)
  File "/usr/local/lib64/python2.7/site-packages/django/template/base.py", line 789, in resolve
    value = self._resolve_lookup(context)
  File "/usr/local/lib64/python2.7/site-packages/django/template/base.py", line 849, in _resolve_lookup
    current = current()
  File "/usr/local/lib64/python2.7/site-packages/django/template/loader_tags.py", line 79, in super
    return mark_safe(self.render(self.context))
  File "/usr/local/lib64/python2.7/site-packages/django/template/loader_tags.py", line 65, in render
    result = block.nodelist.render(context)
  File "/usr/local/lib64/python2.7/site-packages/django/template/base.py", line 905, in render
    bit = self.render_node(node, context)
  File "/usr/local/lib64/python2.7/site-packages/django/template/base.py", line 919, in render_node
    return node.render(context)
  File "/usr/local/lib64/python2.7/site-packages/django/template/defaulttags.py", line 329, in render
    return nodelist.render(context)
  File "/usr/local/lib64/python2.7/site-packages/django/template/base.py", line 905, in render
    bit = self.render_node(node, context)
  File "/usr/local/lib64/python2.7/site-packages/django/template/base.py", line 919, in render_node
    return node.render(context)
  File "/usr/local/lib64/python2.7/site-packages/django/template/defaulttags.py", line 329, in render
    return nodelist.render(context)
  File "/usr/local/lib64/python2.7/site-packages/django/template/base.py", line 905, in render
    bit = self.render_node(node, context)
  File "/usr/local/lib64/python2.7/site-packages/django/template/base.py", line 919, in render_node
    return node.render(context)
  File "/usr/local/lib64/python2.7/site-packages/django/template/defaulttags.py", line 493, in render
    url = reverse(view_name, args=args, kwargs=kwargs, current_app=current_app)
  File "/usr/local/lib64/python2.7/site-packages/django/core/urlresolvers.py", line 578, in reverse
    return force_text(iri_to_uri(resolver._reverse_with_prefix(view, prefix, *args, **kwargs)))
  File "/usr/local/lib64/python2.7/site-packages/django/core/urlresolvers.py", line 432, in _reverse_with_prefix
    self._populate()
  File "/usr/local/lib64/python2.7/site-packages/django/core/urlresolvers.py", line 307, in _populate
    for name in pattern.reverse_dict:
  File "/usr/local/lib64/python2.7/site-packages/django/core/urlresolvers.py", line 337, in reverse_dict
    self._populate()
  File "/usr/local/lib64/python2.7/site-packages/django/core/urlresolvers.py", line 307, in _populate
    for name in pattern.reverse_dict:
  File "/usr/local/lib64/python2.7/site-packages/django/core/urlresolvers.py", line 337, in reverse_dict
    self._populate()
  File "/usr/local/lib64/python2.7/site-packages/django/core/urlresolvers.py", line 284, in _populate
    for pattern in reversed(self.url_patterns):
  File "/usr/local/lib64/python2.7/site-packages/django/core/urlresolvers.py", line 410, in url_patterns
    raise ImproperlyConfigured(msg.format(name=self.urlconf_name))
ImproperlyConfigured: The included urlconf 'None' does not appear to have any patterns in it. If you see valid patterns in the file then the issue is probably caused by a circular import.
[17/Mar/2017 12:46:09] ERROR [/usr/local/lib64/python2.7/site-packages/django/core/handlers/base.py:256] Internal Server Error: /
Traceback (most recent call last):
  File "/usr/local/lib64/python2.7/site-packages/django/core/handlers/base.py", line 164, in get_response
    response = response.render()
  File "/usr/local/lib64/python2.7/site-packages/django/template/response.py", line 158, in render
    self.content = self.rendered_content
  File "/usr/local/lib64/python2.7/site-packages/django/template/response.py", line 135, in rendered_content
    content = template.render(context, self._request)
  File "/usr/local/lib64/python2.7/site-packages/django/template/backends/django.py", line 74, in render
    return self.template.render(context)
  File "/usr/local/lib64/python2.7/site-packages/django/template/base.py", line 210, in render
    return self._render(context)
  File "/usr/local/lib64/python2.7/site-packages/django/template/base.py", line 202, in _render
    return self.nodelist.render(context)
  File "/usr/local/lib64/python2.7/site-packages/django/template/base.py", line 905, in render
    bit = self.render_node(node, context)
  File "/usr/local/lib64/python2.7/site-packages/django/template/base.py", line 919, in render_node
    return node.render(context)
  File "/usr/local/lib64/python2.7/site-packages/django/template/loader_tags.py", line 135, in render
    return compiled_parent._render(context)
  File "/usr/local/lib64/python2.7/site-packages/django/template/base.py", line 202, in _render
    return self.nodelist.render(context)
  File "/usr/local/lib64/python2.7/site-packages/django/template/base.py", line 905, in render
    bit = self.render_node(node, context)
  File "/usr/local/lib64/python2.7/site-packages/django/template/base.py", line 919, in render_node
    return node.render(context)
  File "/usr/local/lib64/python2.7/site-packages/django/template/loader_tags.py", line 65, in render
    result = block.nodelist.render(context)
  File "/usr/local/lib64/python2.7/site-packages/django/template/base.py", line 905, in render
    bit = self.render_node(node, context)
  File "/usr/local/lib64/python2.7/site-packages/django/template/base.py", line 919, in render_node
    return node.render(context)
  File "/usr/local/lib64/python2.7/site-packages/django/template/loader_tags.py", line 65, in render
    result = block.nodelist.render(context)
  File "/usr/local/lib64/python2.7/site-packages/django/template/base.py", line 905, in render
    bit = self.render_node(node, context)
  File "/usr/local/lib64/python2.7/site-packages/django/template/base.py", line 919, in render_node
    return node.render(context)
  File "/usr/local/lib64/python2.7/site-packages/django/template/loader_tags.py", line 65, in render
    result = block.nodelist.render(context)
  File "/usr/local/lib64/python2.7/site-packages/django/template/base.py", line 905, in render
    bit = self.render_node(node, context)
  File "/usr/local/lib64/python2.7/site-packages/django/template/base.py", line 919, in render_node
    return node.render(context)
  File "/usr/local/lib64/python2.7/site-packages/django/template/defaulttags.py", line 329, in render
    return nodelist.render(context)
  File "/usr/local/lib64/python2.7/site-packages/django/template/base.py", line 905, in render
    bit = self.render_node(node, context)
  File "/usr/local/lib64/python2.7/site-packages/django/template/base.py", line 919, in render_node
    return node.render(context)
  File "/usr/local/lib64/python2.7/site-packages/django/template/base.py", line 959, in render
    output = self.filter_expression.resolve(context)
  File "/usr/local/lib64/python2.7/site-packages/django/template/base.py", line 648, in resolve
    obj = self.var.resolve(context)
  File "/usr/local/lib64/python2.7/site-packages/django/template/base.py", line 789, in resolve
    value = self._resolve_lookup(context)
  File "/usr/local/lib64/python2.7/site-packages/django/template/base.py", line 849, in _resolve_lookup
    current = current()
  File "/usr/local/lib64/python2.7/site-packages/django/template/loader_tags.py", line 79, in super
    return mark_safe(self.render(self.context))
  File "/usr/local/lib64/python2.7/site-packages/django/template/loader_tags.py", line 65, in render
    result = block.nodelist.render(context)
  File "/usr/local/lib64/python2.7/site-packages/django/template/base.py", line 905, in render
    bit = self.render_node(node, context)
  File "/usr/local/lib64/python2.7/site-packages/django/template/base.py", line 919, in render_node
    return node.render(context)
  File "/usr/local/lib64/python2.7/site-packages/django/template/defaulttags.py", line 329, in render
    return nodelist.render(context)
  File "/usr/local/lib64/python2.7/site-packages/django/template/base.py", line 905, in render
    bit = self.render_node(node, context)
  File "/usr/local/lib64/python2.7/site-packages/django/template/base.py", line 919, in render_node
    return node.render(context)
  File "/usr/local/lib64/python2.7/site-packages/django/template/defaulttags.py", line 329, in render
    return nodelist.render(context)
  File "/usr/local/lib64/python2.7/site-packages/django/template/base.py", line 905, in render
    bit = self.render_node(node, context)
  File "/usr/local/lib64/python2.7/site-packages/django/template/base.py", line 919, in render_node
    return node.render(context)
  File "/usr/local/lib64/python2.7/site-packages/django/template/defaulttags.py", line 493, in render
    url = reverse(view_name, args=args, kwargs=kwargs, current_app=current_app)
  File "/usr/local/lib64/python2.7/site-packages/django/core/urlresolvers.py", line 578, in reverse
    return force_text(iri_to_uri(resolver._reverse_with_prefix(view, prefix, *args, **kwargs)))
  File "/usr/local/lib64/python2.7/site-packages/django/core/urlresolvers.py", line 432, in _reverse_with_prefix
    self._populate()
  File "/usr/local/lib64/python2.7/site-packages/django/core/urlresolvers.py", line 307, in _populate
    for name in pattern.reverse_dict:
  File "/usr/local/lib64/python2.7/site-packages/django/core/urlresolvers.py", line 337, in reverse_dict
    self._populate()
  File "/usr/local/lib64/python2.7/site-packages/django/core/urlresolvers.py", line 307, in _populate
    for name in pattern.reverse_dict:
  File "/usr/local/lib64/python2.7/site-packages/django/core/urlresolvers.py", line 337, in reverse_dict
    self._populate()
  File "/usr/local/lib64/python2.7/site-packages/django/core/urlresolvers.py", line 284, in _populate
    for pattern in reversed(self.url_patterns):
  File "/usr/local/lib64/python2.7/site-packages/django/core/urlresolvers.py", line 410, in url_patterns
    raise ImproperlyConfigured(msg.format(name=self.urlconf_name))
ImproperlyConfigured: The included urlconf 'None' does not appear to have any patterns in it. If you see valid patterns in the file then the issue is probably caused by a circular import.
[17/Mar/2017 12:46:20] ERROR [/usr/local/lib64/python2.7/site-packages/django/core/handlers/base.py:256] Internal Server Error: /
Traceback (most recent call last):
  File "/usr/local/lib64/python2.7/site-packages/django/core/handlers/base.py", line 164, in get_response
    response = response.render()
  File "/usr/local/lib64/python2.7/site-packages/django/template/response.py", line 158, in render
    self.content = self.rendered_content
  File "/usr/local/lib64/python2.7/site-packages/django/template/response.py", line 135, in rendered_content
    content = template.render(context, self._request)
  File "/usr/local/lib64/python2.7/site-packages/django/template/backends/django.py", line 74, in render
    return self.template.render(context)
  File "/usr/local/lib64/python2.7/site-packages/django/template/base.py", line 210, in render
    return self._render(context)
  File "/usr/local/lib64/python2.7/site-packages/django/template/base.py", line 202, in _render
    return self.nodelist.render(context)
  File "/usr/local/lib64/python2.7/site-packages/django/template/base.py", line 905, in render
    bit = self.render_node(node, context)
  File "/usr/local/lib64/python2.7/site-packages/django/template/base.py", line 919, in render_node
    return node.render(context)
  File "/usr/local/lib64/python2.7/site-packages/django/template/loader_tags.py", line 135, in render
    return compiled_parent._render(context)
  File "/usr/local/lib64/python2.7/site-packages/django/template/base.py", line 202, in _render
    return self.nodelist.render(context)
  File "/usr/local/lib64/python2.7/site-packages/django/template/base.py", line 905, in render
    bit = self.render_node(node, context)
  File "/usr/local/lib64/python2.7/site-packages/django/template/base.py", line 919, in render_node
    return node.render(context)
  File "/usr/local/lib64/python2.7/site-packages/django/template/loader_tags.py", line 65, in render
    result = block.nodelist.render(context)
  File "/usr/local/lib64/python2.7/site-packages/django/template/base.py", line 905, in render
    bit = self.render_node(node, context)
  File "/usr/local/lib64/python2.7/site-packages/django/template/base.py", line 919, in render_node
    return node.render(context)
  File "/usr/local/lib64/python2.7/site-packages/django/template/loader_tags.py", line 65, in render
    result = block.nodelist.render(context)
  File "/usr/local/lib64/python2.7/site-packages/django/template/base.py", line 905, in render
    bit = self.render_node(node, context)
  File "/usr/local/lib64/python2.7/site-packages/django/template/base.py", line 919, in render_node
    return node.render(context)
  File "/usr/local/lib64/python2.7/site-packages/django/template/loader_tags.py", line 65, in render
    result = block.nodelist.render(context)
  File "/usr/local/lib64/python2.7/site-packages/django/template/base.py", line 905, in render
    bit = self.render_node(node, context)
  File "/usr/local/lib64/python2.7/site-packages/django/template/base.py", line 919, in render_node
    return node.render(context)
  File "/usr/local/lib64/python2.7/site-packages/django/template/defaulttags.py", line 329, in render
    return nodelist.render(context)
  File "/usr/local/lib64/python2.7/site-packages/django/template/base.py", line 905, in render
    bit = self.render_node(node, context)
  File "/usr/local/lib64/python2.7/site-packages/django/template/base.py", line 919, in render_node
    return node.render(context)
  File "/usr/local/lib64/python2.7/site-packages/django/template/base.py", line 959, in render
    output = self.filter_expression.resolve(context)
  File "/usr/local/lib64/python2.7/site-packages/django/template/base.py", line 648, in resolve
    obj = self.var.resolve(context)
  File "/usr/local/lib64/python2.7/site-packages/django/template/base.py", line 789, in resolve
    value = self._resolve_lookup(context)
  File "/usr/local/lib64/python2.7/site-packages/django/template/base.py", line 849, in _resolve_lookup
    current = current()
  File "/usr/local/lib64/python2.7/site-packages/django/template/loader_tags.py", line 79, in super
    return mark_safe(self.render(self.context))
  File "/usr/local/lib64/python2.7/site-packages/django/template/loader_tags.py", line 65, in render
    result = block.nodelist.render(context)
  File "/usr/local/lib64/python2.7/site-packages/django/template/base.py", line 905, in render
    bit = self.render_node(node, context)
  File "/usr/local/lib64/python2.7/site-packages/django/template/base.py", line 919, in render_node
    return node.render(context)
  File "/usr/local/lib64/python2.7/site-packages/django/template/defaulttags.py", line 329, in render
    return nodelist.render(context)
  File "/usr/local/lib64/python2.7/site-packages/django/template/base.py", line 905, in render
    bit = self.render_node(node, context)
  File "/usr/local/lib64/python2.7/site-packages/django/template/base.py", line 919, in render_node
    return node.render(context)
  File "/usr/local/lib64/python2.7/site-packages/django/template/defaulttags.py", line 329, in render
    return nodelist.render(context)
  File "/usr/local/lib64/python2.7/site-packages/django/template/base.py", line 905, in render
    bit = self.render_node(node, context)
  File "/usr/local/lib64/python2.7/site-packages/django/template/base.py", line 919, in render_node
    return node.render(context)
  File "/usr/local/lib64/python2.7/site-packages/django/template/defaulttags.py", line 493, in render
    url = reverse(view_name, args=args, kwargs=kwargs, current_app=current_app)
  File "/usr/local/lib64/python2.7/site-packages/django/core/urlresolvers.py", line 578, in reverse
    return force_text(iri_to_uri(resolver._reverse_with_prefix(view, prefix, *args, **kwargs)))
  File "/usr/local/lib64/python2.7/site-packages/django/core/urlresolvers.py", line 432, in _reverse_with_prefix
    self._populate()
  File "/usr/local/lib64/python2.7/site-packages/django/core/urlresolvers.py", line 307, in _populate
    for name in pattern.reverse_dict:
  File "/usr/local/lib64/python2.7/site-packages/django/core/urlresolvers.py", line 337, in reverse_dict
    self._populate()
  File "/usr/local/lib64/python2.7/site-packages/django/core/urlresolvers.py", line 307, in _populate
    for name in pattern.reverse_dict:
  File "/usr/local/lib64/python2.7/site-packages/django/core/urlresolvers.py", line 337, in reverse_dict
    self._populate()
  File "/usr/local/lib64/python2.7/site-packages/django/core/urlresolvers.py", line 284, in _populate
    for pattern in reversed(self.url_patterns):
  File "/usr/local/lib64/python2.7/site-packages/django/core/urlresolvers.py", line 410, in url_patterns
    raise ImproperlyConfigured(msg.format(name=self.urlconf_name))
ImproperlyConfigured: The included urlconf 'None' does not appear to have any patterns in it. If you see valid patterns in the file then the issue is probably caused by a circular import.
[20/Mar/2017 04:57:08] ERROR [/usr/local/lib64/python2.7/site-packages/django/core/handlers/base.py:256] Internal Server Error: /twitter_count/realtime_jp/
Traceback (most recent call last):
  File "/usr/local/lib64/python2.7/site-packages/django/core/handlers/base.py", line 132, in get_response
    response = wrapped_callback(request, *callback_args, **callback_kwargs)
  File "/usr/local/lib64/python2.7/site-packages/django/views/generic/base.py", line 71, in view
    return self.dispatch(request, *args, **kwargs)
  File "/usr/local/lib64/python2.7/site-packages/django/views/generic/base.py", line 89, in dispatch
    return handler(request, *args, **kwargs)
  File "/var/www/instag_new/src/twitter_count/views.py", line 50, in get
    twitter_ranking_list = twitter_ranking_list[int(url_from)-1:url_to]
ValueError: invalid literal for int() with base 10: ''
[22/Mar/2017 02:23:32] ERROR [/usr/local/lib64/python2.7/site-packages/django/core/handlers/base.py:256] Internal Server Error: /twitter_count/realtime_jp/
Traceback (most recent call last):
  File "/usr/local/lib64/python2.7/site-packages/django/core/handlers/base.py", line 132, in get_response
    response = wrapped_callback(request, *callback_args, **callback_kwargs)
  File "/usr/local/lib64/python2.7/site-packages/django/views/generic/base.py", line 71, in view
    return self.dispatch(request, *args, **kwargs)
  File "/usr/local/lib64/python2.7/site-packages/django/views/generic/base.py", line 89, in dispatch
    return handler(request, *args, **kwargs)
  File "/var/www/instag_new/src/twitter_count/views.py", line 50, in get
    twitter_ranking_list = twitter_ranking_list[int(url_from)-1:url_to]
ValueError: invalid literal for int() with base 10: ''
[22/Mar/2017 02:39:59] ERROR [/usr/local/lib64/python2.7/site-packages/django/core/handlers/base.py:256] Internal Server Error: /twitter_count/realtime_ko/
Traceback (most recent call last):
  File "/usr/local/lib64/python2.7/site-packages/django/core/handlers/base.py", line 132, in get_response
    response = wrapped_callback(request, *callback_args, **callback_kwargs)
  File "/usr/local/lib64/python2.7/site-packages/django/views/generic/base.py", line 71, in view
    return self.dispatch(request, *args, **kwargs)
  File "/usr/local/lib64/python2.7/site-packages/django/views/generic/base.py", line 89, in dispatch
    return handler(request, *args, **kwargs)
  File "/var/www/instag_new/src/twitter_count/views.py", line 81, in get
    twitter_ranking_list = twitter_ranking_list[int(url_from)-1:url_to]
ValueError: invalid literal for int() with base 10: ''
[22/Mar/2017 02:40:11] ERROR [/usr/local/lib64/python2.7/site-packages/django/core/handlers/base.py:256] Internal Server Error: /twitter_count/realtime_ko/
Traceback (most recent call last):
  File "/usr/local/lib64/python2.7/site-packages/django/core/handlers/base.py", line 132, in get_response
    response = wrapped_callback(request, *callback_args, **callback_kwargs)
  File "/usr/local/lib64/python2.7/site-packages/django/views/generic/base.py", line 71, in view
    return self.dispatch(request, *args, **kwargs)
  File "/usr/local/lib64/python2.7/site-packages/django/views/generic/base.py", line 89, in dispatch
    return handler(request, *args, **kwargs)
  File "/var/www/instag_new/src/twitter_count/views.py", line 81, in get
    twitter_ranking_list = twitter_ranking_list[int(url_from)-1:url_to]
ValueError: invalid literal for int() with base 10: ''
[22/Mar/2017 17:12:18] ERROR [/usr/local/lib64/python2.7/site-packages/django/core/handlers/base.py:256] Internal Server Error: /twitter_count/realtime_jp/
Traceback (most recent call last):
  File "/usr/local/lib64/python2.7/site-packages/django/core/handlers/base.py", line 132, in get_response
    response = wrapped_callback(request, *callback_args, **callback_kwargs)
  File "/usr/local/lib64/python2.7/site-packages/django/views/generic/base.py", line 71, in view
    return self.dispatch(request, *args, **kwargs)
  File "/usr/local/lib64/python2.7/site-packages/django/views/generic/base.py", line 89, in dispatch
    return handler(request, *args, **kwargs)
  File "/var/www/instag_new/src/twitter_count/views.py", line 50, in get
    twitter_ranking_list = twitter_ranking_list[int(url_from)-1:url_to]
ValueError: invalid literal for int() with base 10: ''
[27/Mar/2017 02:35:58] ERROR [/usr/local/lib64/python2.7/site-packages/django/core/handlers/base.py:256] Internal Server Error: /twitter_count/realtime_jp/
Traceback (most recent call last):
  File "/usr/local/lib64/python2.7/site-packages/django/core/handlers/base.py", line 132, in get_response
    response = wrapped_callback(request, *callback_args, **callback_kwargs)
  File "/usr/local/lib64/python2.7/site-packages/django/views/generic/base.py", line 71, in view
    return self.dispatch(request, *args, **kwargs)
  File "/usr/local/lib64/python2.7/site-packages/django/views/generic/base.py", line 89, in dispatch
    return handler(request, *args, **kwargs)
  File "/var/www/instag_new/src/twitter_count/views.py", line 50, in get
    twitter_ranking_list = twitter_ranking_list[int(url_from)-1:url_to]
ValueError: invalid literal for int() with base 10: ''
[27/Mar/2017 09:01:57] ERROR [/usr/local/lib64/python2.7/site-packages/django/core/handlers/base.py:256] Internal Server Error: /twitter_count/realtime_ko/
Traceback (most recent call last):
  File "/usr/local/lib64/python2.7/site-packages/django/core/handlers/base.py", line 132, in get_response
    response = wrapped_callback(request, *callback_args, **callback_kwargs)
  File "/usr/local/lib64/python2.7/site-packages/django/views/generic/base.py", line 71, in view
    return self.dispatch(request, *args, **kwargs)
  File "/usr/local/lib64/python2.7/site-packages/django/views/generic/base.py", line 89, in dispatch
    return handler(request, *args, **kwargs)
  File "/var/www/instag_new/src/twitter_count/views.py", line 81, in get
    twitter_ranking_list = twitter_ranking_list[int(url_from)-1:url_to]
ValueError: invalid literal for int() with base 10: ''
[31/Mar/2017 08:40:52] ERROR [/usr/local/lib64/python2.7/site-packages/django/core/handlers/base.py:256] Internal Server Error: /twitter_count/realtime_jp/
Traceback (most recent call last):
  File "/usr/local/lib64/python2.7/site-packages/django/core/handlers/base.py", line 132, in get_response
    response = wrapped_callback(request, *callback_args, **callback_kwargs)
  File "/usr/local/lib64/python2.7/site-packages/django/views/generic/base.py", line 71, in view
    return self.dispatch(request, *args, **kwargs)
  File "/usr/local/lib64/python2.7/site-packages/django/views/generic/base.py", line 89, in dispatch
    return handler(request, *args, **kwargs)
  File "/var/www/instag_new/src/twitter_count/views.py", line 50, in get
    twitter_ranking_list = twitter_ranking_list[int(url_from)-1:url_to]
ValueError: invalid literal for int() with base 10: ''
[03/Apr/2017 15:13:12] ERROR [/usr/local/lib64/python2.7/site-packages/django/core/handlers/base.py:256] Internal Server Error: /twitter_count/realtime_ko/
Traceback (most recent call last):
  File "/usr/local/lib64/python2.7/site-packages/django/core/handlers/base.py", line 132, in get_response
    response = wrapped_callback(request, *callback_args, **callback_kwargs)
  File "/usr/local/lib64/python2.7/site-packages/django/views/generic/base.py", line 71, in view
    return self.dispatch(request, *args, **kwargs)
  File "/usr/local/lib64/python2.7/site-packages/django/views/generic/base.py", line 89, in dispatch
    return handler(request, *args, **kwargs)
  File "/var/www/instag_new/src/twitter_count/views.py", line 81, in get
    twitter_ranking_list = twitter_ranking_list[int(url_from)-1:url_to]
ValueError: invalid literal for int() with base 10: ''
[09/Apr/2017 13:12:21] ERROR [/usr/local/lib64/python2.7/site-packages/django/core/handlers/base.py:256] Internal Server Error: /twitter_count/realtime_jp/
Traceback (most recent call last):
  File "/usr/local/lib64/python2.7/site-packages/django/core/handlers/base.py", line 132, in get_response
    response = wrapped_callback(request, *callback_args, **callback_kwargs)
  File "/usr/local/lib64/python2.7/site-packages/django/views/generic/base.py", line 71, in view
    return self.dispatch(request, *args, **kwargs)
  File "/usr/local/lib64/python2.7/site-packages/django/views/generic/base.py", line 89, in dispatch
    return handler(request, *args, **kwargs)
  File "/var/www/instag_new/src/twitter_count/views.py", line 50, in get
    twitter_ranking_list = twitter_ranking_list[int(url_from)-1:url_to]
ValueError: invalid literal for int() with base 10: ''
[09/Apr/2017 13:23:02] ERROR [/usr/local/lib64/python2.7/site-packages/django/core/handlers/base.py:256] Internal Server Error: /admin/
Traceback (most recent call last):
  File "/usr/local/lib64/python2.7/site-packages/django/core/handlers/base.py", line 132, in get_response
    response = wrapped_callback(request, *callback_args, **callback_kwargs)
  File "/usr/local/lib64/python2.7/site-packages/django/contrib/admin/sites.py", line 254, in wrapper
    return self.admin_view(view, cacheable)(*args, **kwargs)
  File "/usr/local/lib64/python2.7/site-packages/django/utils/decorators.py", line 110, in _wrapped_view
    response = view_func(request, *args, **kwargs)
  File "/usr/local/lib64/python2.7/site-packages/django/views/decorators/cache.py", line 57, in _wrapped_view_func
    response = view_func(request, *args, **kwargs)
  File "/usr/local/lib64/python2.7/site-packages/django/contrib/admin/sites.py", line 223, in inner
    if request.path == reverse('admin:logout', current_app=self.name):
  File "/usr/local/lib64/python2.7/site-packages/django/core/urlresolvers.py", line 578, in reverse
    return force_text(iri_to_uri(resolver._reverse_with_prefix(view, prefix, *args, **kwargs)))
  File "/usr/local/lib64/python2.7/site-packages/django/core/urlresolvers.py", line 432, in _reverse_with_prefix
    self._populate()
  File "/usr/local/lib64/python2.7/site-packages/django/core/urlresolvers.py", line 307, in _populate
    for name in pattern.reverse_dict:
  File "/usr/local/lib64/python2.7/site-packages/django/core/urlresolvers.py", line 337, in reverse_dict
    self._populate()
  File "/usr/local/lib64/python2.7/site-packages/django/core/urlresolvers.py", line 307, in _populate
    for name in pattern.reverse_dict:
  File "/usr/local/lib64/python2.7/site-packages/django/core/urlresolvers.py", line 337, in reverse_dict
    self._populate()
  File "/usr/local/lib64/python2.7/site-packages/django/core/urlresolvers.py", line 284, in _populate
    for pattern in reversed(self.url_patterns):
  File "/usr/local/lib64/python2.7/site-packages/django/core/urlresolvers.py", line 410, in url_patterns
    raise ImproperlyConfigured(msg.format(name=self.urlconf_name))
ImproperlyConfigured: The included urlconf 'None' does not appear to have any patterns in it. If you see valid patterns in the file then the issue is probably caused by a circular import.
[13/Apr/2017 00:11:40] ERROR [/usr/local/lib64/python2.7/site-packages/django/core/handlers/base.py:256] Internal Server Error: /twitter_count/realtime_ko/
Traceback (most recent call last):
  File "/usr/local/lib64/python2.7/site-packages/django/core/handlers/base.py", line 132, in get_response
    response = wrapped_callback(request, *callback_args, **callback_kwargs)
  File "/usr/local/lib64/python2.7/site-packages/django/views/generic/base.py", line 71, in view
    return self.dispatch(request, *args, **kwargs)
  File "/usr/local/lib64/python2.7/site-packages/django/views/generic/base.py", line 89, in dispatch
    return handler(request, *args, **kwargs)
  File "/var/www/instag_new/src/twitter_count/views.py", line 81, in get
    twitter_ranking_list = twitter_ranking_list[int(url_from)-1:url_to]
ValueError: invalid literal for int() with base 10: ''
[14/Apr/2017 16:13:42] ERROR [/usr/local/lib64/python2.7/site-packages/django/core/handlers/base.py:256] Internal Server Error: /twitter_count/realtime_ko/
Traceback (most recent call last):
  File "/usr/local/lib64/python2.7/site-packages/django/core/handlers/base.py", line 132, in get_response
    response = wrapped_callback(request, *callback_args, **callback_kwargs)
  File "/usr/local/lib64/python2.7/site-packages/django/views/generic/base.py", line 71, in view
    return self.dispatch(request, *args, **kwargs)
  File "/usr/local/lib64/python2.7/site-packages/django/views/generic/base.py", line 89, in dispatch
    return handler(request, *args, **kwargs)
  File "/var/www/instag_new/src/twitter_count/views.py", line 81, in get
    twitter_ranking_list = twitter_ranking_list[int(url_from)-1:url_to]
ValueError: invalid literal for int() with base 10: ''
[21/Apr/2017 17:15:22] INFO [/var/www/instag_new/src/profiles/signals.py:17] New user profile for kimnam <orange3311@gmail.com> created
[21/Apr/2017 17:16:18] ERROR [/usr/local/lib64/python2.7/site-packages/django/core/handlers/base.py:256] Internal Server Error: /
Traceback (most recent call last):
  File "/usr/local/lib64/python2.7/site-packages/django/core/handlers/base.py", line 119, in get_response
    resolver_match = resolver.resolve(request.path_info)
  File "/usr/local/lib64/python2.7/site-packages/django/core/urlresolvers.py", line 365, in resolve
    for pattern in self.url_patterns:
  File "/usr/local/lib64/python2.7/site-packages/django/core/urlresolvers.py", line 401, in url_patterns
    patterns = getattr(self.urlconf_module, "urlpatterns", self.urlconf_module)
  File "/usr/local/lib64/python2.7/site-packages/django/core/urlresolvers.py", line 395, in urlconf_module
    self._urlconf_module = import_module(self.urlconf_name)
  File "/usr/lib64/python2.7/importlib/__init__.py", line 37, in import_module
    __import__(name)
  File "/var/www/instag_new/src/instag/urls.py", line 9, in <module>
    import felica.urls
  File "/var/www/instag_new/src/felica/urls.py", line 2, in <module>
    from . import views
  File "/var/www/instag_new/src/felica/views.py", line 14, in <module>
    from .utils import paginator_list
  File "/var/www/instag_new/src/felica/utils.py", line 4, in <module>
    import xlrd
ImportError: No module named xlrd
[21/Apr/2017 17:16:19] ERROR [/usr/local/lib64/python2.7/site-packages/django/core/handlers/base.py:256] Internal Server Error: /
Traceback (most recent call last):
  File "/usr/local/lib64/python2.7/site-packages/django/core/handlers/base.py", line 119, in get_response
    resolver_match = resolver.resolve(request.path_info)
  File "/usr/local/lib64/python2.7/site-packages/django/core/urlresolvers.py", line 365, in resolve
    for pattern in self.url_patterns:
  File "/usr/local/lib64/python2.7/site-packages/django/core/urlresolvers.py", line 401, in url_patterns
    patterns = getattr(self.urlconf_module, "urlpatterns", self.urlconf_module)
  File "/usr/local/lib64/python2.7/site-packages/django/core/urlresolvers.py", line 395, in urlconf_module
    self._urlconf_module = import_module(self.urlconf_name)
  File "/usr/lib64/python2.7/importlib/__init__.py", line 37, in import_module
    __import__(name)
  File "/var/www/instag_new/src/instag/urls.py", line 9, in <module>
    import felica.urls
  File "/var/www/instag_new/src/felica/urls.py", line 2, in <module>
    from . import views
  File "/var/www/instag_new/src/felica/views.py", line 14, in <module>
    from .utils import paginator_list
  File "/var/www/instag_new/src/felica/utils.py", line 4, in <module>
    import xlrd
ImportError: No module named xlrd
[21/Apr/2017 17:16:19] ERROR [/usr/local/lib64/python2.7/site-packages/django/core/handlers/base.py:256] Internal Server Error: /favicon.ico
Traceback (most recent call last):
  File "/usr/local/lib64/python2.7/site-packages/django/core/handlers/base.py", line 108, in get_response
    response = middleware_method(request)
  File "/usr/local/lib64/python2.7/site-packages/django/middleware/common.py", line 74, in process_request
    if (not urlresolvers.is_valid_path(request.path_info, urlconf) and
  File "/usr/local/lib64/python2.7/site-packages/django/core/urlresolvers.py", line 646, in is_valid_path
    resolve(path, urlconf)
  File "/usr/local/lib64/python2.7/site-packages/django/core/urlresolvers.py", line 521, in resolve
    return get_resolver(urlconf).resolve(path)
  File "/usr/local/lib64/python2.7/site-packages/django/core/urlresolvers.py", line 365, in resolve
    for pattern in self.url_patterns:
  File "/usr/local/lib64/python2.7/site-packages/django/core/urlresolvers.py", line 401, in url_patterns
    patterns = getattr(self.urlconf_module, "urlpatterns", self.urlconf_module)
  File "/usr/local/lib64/python2.7/site-packages/django/core/urlresolvers.py", line 395, in urlconf_module
    self._urlconf_module = import_module(self.urlconf_name)
  File "/usr/lib64/python2.7/importlib/__init__.py", line 37, in import_module
    __import__(name)
  File "/var/www/instag_new/src/instag/urls.py", line 9, in <module>
    import felica.urls
  File "/var/www/instag_new/src/felica/urls.py", line 2, in <module>
    from . import views
  File "/var/www/instag_new/src/felica/views.py", line 14, in <module>
    from .utils import paginator_list
  File "/var/www/instag_new/src/felica/utils.py", line 4, in <module>
    import xlrd
ImportError: No module named xlrd
[21/Apr/2017 17:16:26] ERROR [/usr/local/lib64/python2.7/site-packages/django/core/handlers/base.py:256] Internal Server Error: /
Traceback (most recent call last):
  File "/usr/local/lib64/python2.7/site-packages/django/core/handlers/base.py", line 119, in get_response
    resolver_match = resolver.resolve(request.path_info)
  File "/usr/local/lib64/python2.7/site-packages/django/core/urlresolvers.py", line 365, in resolve
    for pattern in self.url_patterns:
  File "/usr/local/lib64/python2.7/site-packages/django/core/urlresolvers.py", line 401, in url_patterns
    patterns = getattr(self.urlconf_module, "urlpatterns", self.urlconf_module)
  File "/usr/local/lib64/python2.7/site-packages/django/core/urlresolvers.py", line 395, in urlconf_module
    self._urlconf_module = import_module(self.urlconf_name)
  File "/usr/lib64/python2.7/importlib/__init__.py", line 37, in import_module
    __import__(name)
  File "/var/www/instag_new/src/instag/urls.py", line 9, in <module>
    import felica.urls
  File "/var/www/instag_new/src/felica/urls.py", line 2, in <module>
    from . import views
  File "/var/www/instag_new/src/felica/views.py", line 14, in <module>
    from .utils import paginator_list
  File "/var/www/instag_new/src/felica/utils.py", line 4, in <module>
    import xlrd
ImportError: No module named xlrd
[21/Apr/2017 17:16:27] ERROR [/usr/local/lib64/python2.7/site-packages/django/core/handlers/base.py:256] Internal Server Error: /favicon.ico
Traceback (most recent call last):
  File "/usr/local/lib64/python2.7/site-packages/django/core/handlers/base.py", line 108, in get_response
    response = middleware_method(request)
  File "/usr/local/lib64/python2.7/site-packages/django/middleware/common.py", line 74, in process_request
    if (not urlresolvers.is_valid_path(request.path_info, urlconf) and
  File "/usr/local/lib64/python2.7/site-packages/django/core/urlresolvers.py", line 646, in is_valid_path
    resolve(path, urlconf)
  File "/usr/local/lib64/python2.7/site-packages/django/core/urlresolvers.py", line 521, in resolve
    return get_resolver(urlconf).resolve(path)
  File "/usr/local/lib64/python2.7/site-packages/django/core/urlresolvers.py", line 365, in resolve
    for pattern in self.url_patterns:
  File "/usr/local/lib64/python2.7/site-packages/django/core/urlresolvers.py", line 401, in url_patterns
    patterns = getattr(self.urlconf_module, "urlpatterns", self.urlconf_module)
  File "/usr/local/lib64/python2.7/site-packages/django/core/urlresolvers.py", line 395, in urlconf_module
    self._urlconf_module = import_module(self.urlconf_name)
  File "/usr/lib64/python2.7/importlib/__init__.py", line 37, in import_module
    __import__(name)
  File "/var/www/instag_new/src/instag/urls.py", line 9, in <module>
    import felica.urls
  File "/var/www/instag_new/src/felica/urls.py", line 2, in <module>
    from . import views
  File "/var/www/instag_new/src/felica/views.py", line 14, in <module>
    from .utils import paginator_list
  File "/var/www/instag_new/src/felica/utils.py", line 4, in <module>
    import xlrd
ImportError: No module named xlrd
[21/Apr/2017 17:18:01] ERROR [/usr/local/lib64/python2.7/site-packages/django/core/handlers/base.py:256] Internal Server Error: /twitter_count/realtime_jp/
Traceback (most recent call last):
  File "/usr/local/lib64/python2.7/site-packages/django/core/handlers/base.py", line 119, in get_response
    resolver_match = resolver.resolve(request.path_info)
  File "/usr/local/lib64/python2.7/site-packages/django/core/urlresolvers.py", line 365, in resolve
    for pattern in self.url_patterns:
  File "/usr/local/lib64/python2.7/site-packages/django/core/urlresolvers.py", line 401, in url_patterns
    patterns = getattr(self.urlconf_module, "urlpatterns", self.urlconf_module)
  File "/usr/local/lib64/python2.7/site-packages/django/core/urlresolvers.py", line 395, in urlconf_module
    self._urlconf_module = import_module(self.urlconf_name)
  File "/usr/lib64/python2.7/importlib/__init__.py", line 37, in import_module
    __import__(name)
  File "/var/www/instag_new/src/instag/urls.py", line 9, in <module>
    import felica.urls
  File "/var/www/instag_new/src/felica/urls.py", line 2, in <module>
    from . import views
  File "/var/www/instag_new/src/felica/views.py", line 14, in <module>
    from .utils import paginator_list
  File "/var/www/instag_new/src/felica/utils.py", line 4, in <module>
    import xlrd
ImportError: No module named xlrd
[21/Apr/2017 17:18:11] ERROR [/usr/local/lib64/python2.7/site-packages/django/core/handlers/base.py:256] Internal Server Error: /
Traceback (most recent call last):
  File "/usr/local/lib64/python2.7/site-packages/django/core/handlers/base.py", line 119, in get_response
    resolver_match = resolver.resolve(request.path_info)
  File "/usr/local/lib64/python2.7/site-packages/django/core/urlresolvers.py", line 365, in resolve
    for pattern in self.url_patterns:
  File "/usr/local/lib64/python2.7/site-packages/django/core/urlresolvers.py", line 401, in url_patterns
    patterns = getattr(self.urlconf_module, "urlpatterns", self.urlconf_module)
  File "/usr/local/lib64/python2.7/site-packages/django/core/urlresolvers.py", line 395, in urlconf_module
    self._urlconf_module = import_module(self.urlconf_name)
  File "/usr/lib64/python2.7/importlib/__init__.py", line 37, in import_module
    __import__(name)
  File "/var/www/instag_new/src/instag/urls.py", line 9, in <module>
    import felica.urls
  File "/var/www/instag_new/src/felica/urls.py", line 2, in <module>
    from . import views
  File "/var/www/instag_new/src/felica/views.py", line 14, in <module>
    from .utils import paginator_list
  File "/var/www/instag_new/src/felica/utils.py", line 4, in <module>
    import xlrd
ImportError: No module named xlrd
[21/Apr/2017 17:18:12] ERROR [/usr/local/lib64/python2.7/site-packages/django/core/handlers/base.py:256] Internal Server Error: /favicon.ico
Traceback (most recent call last):
  File "/usr/local/lib64/python2.7/site-packages/django/core/handlers/base.py", line 108, in get_response
    response = middleware_method(request)
  File "/usr/local/lib64/python2.7/site-packages/django/middleware/common.py", line 74, in process_request
    if (not urlresolvers.is_valid_path(request.path_info, urlconf) and
  File "/usr/local/lib64/python2.7/site-packages/django/core/urlresolvers.py", line 646, in is_valid_path
    resolve(path, urlconf)
  File "/usr/local/lib64/python2.7/site-packages/django/core/urlresolvers.py", line 521, in resolve
    return get_resolver(urlconf).resolve(path)
  File "/usr/local/lib64/python2.7/site-packages/django/core/urlresolvers.py", line 365, in resolve
    for pattern in self.url_patterns:
  File "/usr/local/lib64/python2.7/site-packages/django/core/urlresolvers.py", line 401, in url_patterns
    patterns = getattr(self.urlconf_module, "urlpatterns", self.urlconf_module)
  File "/usr/local/lib64/python2.7/site-packages/django/core/urlresolvers.py", line 395, in urlconf_module
    self._urlconf_module = import_module(self.urlconf_name)
  File "/usr/lib64/python2.7/importlib/__init__.py", line 37, in import_module
    __import__(name)
  File "/var/www/instag_new/src/instag/urls.py", line 9, in <module>
    import felica.urls
  File "/var/www/instag_new/src/felica/urls.py", line 2, in <module>
    from . import views
  File "/var/www/instag_new/src/felica/views.py", line 14, in <module>
    from .utils import paginator_list
  File "/var/www/instag_new/src/felica/utils.py", line 4, in <module>
    import xlrd
ImportError: No module named xlrd
[21/Apr/2017 17:18:13] ERROR [/usr/local/lib64/python2.7/site-packages/django/core/handlers/base.py:256] Internal Server Error: /
Traceback (most recent call last):
  File "/usr/local/lib64/python2.7/site-packages/django/core/handlers/base.py", line 119, in get_response
    resolver_match = resolver.resolve(request.path_info)
  File "/usr/local/lib64/python2.7/site-packages/django/core/urlresolvers.py", line 365, in resolve
    for pattern in self.url_patterns:
  File "/usr/local/lib64/python2.7/site-packages/django/core/urlresolvers.py", line 401, in url_patterns
    patterns = getattr(self.urlconf_module, "urlpatterns", self.urlconf_module)
  File "/usr/local/lib64/python2.7/site-packages/django/core/urlresolvers.py", line 395, in urlconf_module
    self._urlconf_module = import_module(self.urlconf_name)
  File "/usr/lib64/python2.7/importlib/__init__.py", line 37, in import_module
    __import__(name)
  File "/var/www/instag_new/src/instag/urls.py", line 9, in <module>
    import felica.urls
  File "/var/www/instag_new/src/felica/urls.py", line 2, in <module>
    from . import views
  File "/var/www/instag_new/src/felica/views.py", line 14, in <module>
    from .utils import paginator_list
  File "/var/www/instag_new/src/felica/utils.py", line 4, in <module>
    import xlrd
ImportError: No module named xlrd
[21/Apr/2017 17:18:14] ERROR [/usr/local/lib64/python2.7/site-packages/django/core/handlers/base.py:256] Internal Server Error: /favicon.ico
Traceback (most recent call last):
  File "/usr/local/lib64/python2.7/site-packages/django/core/handlers/base.py", line 108, in get_response
    response = middleware_method(request)
  File "/usr/local/lib64/python2.7/site-packages/django/middleware/common.py", line 74, in process_request
    if (not urlresolvers.is_valid_path(request.path_info, urlconf) and
  File "/usr/local/lib64/python2.7/site-packages/django/core/urlresolvers.py", line 646, in is_valid_path
    resolve(path, urlconf)
  File "/usr/local/lib64/python2.7/site-packages/django/core/urlresolvers.py", line 521, in resolve
    return get_resolver(urlconf).resolve(path)
  File "/usr/local/lib64/python2.7/site-packages/django/core/urlresolvers.py", line 365, in resolve
    for pattern in self.url_patterns:
  File "/usr/local/lib64/python2.7/site-packages/django/core/urlresolvers.py", line 401, in url_patterns
    patterns = getattr(self.urlconf_module, "urlpatterns", self.urlconf_module)
  File "/usr/local/lib64/python2.7/site-packages/django/core/urlresolvers.py", line 395, in urlconf_module
    self._urlconf_module = import_module(self.urlconf_name)
  File "/usr/lib64/python2.7/importlib/__init__.py", line 37, in import_module
    __import__(name)
  File "/var/www/instag_new/src/instag/urls.py", line 9, in <module>
    import felica.urls
  File "/var/www/instag_new/src/felica/urls.py", line 2, in <module>
    from . import views
  File "/var/www/instag_new/src/felica/views.py", line 14, in <module>
    from .utils import paginator_list
  File "/var/www/instag_new/src/felica/utils.py", line 4, in <module>
    import xlrd
ImportError: No module named xlrd
[21/Apr/2017 17:18:53] ERROR [/usr/local/lib64/python2.7/site-packages/django/core/handlers/base.py:256] Internal Server Error: /
Traceback (most recent call last):
  File "/usr/local/lib64/python2.7/site-packages/django/core/handlers/base.py", line 119, in get_response
    resolver_match = resolver.resolve(request.path_info)
  File "/usr/local/lib64/python2.7/site-packages/django/core/urlresolvers.py", line 365, in resolve
    for pattern in self.url_patterns:
  File "/usr/local/lib64/python2.7/site-packages/django/core/urlresolvers.py", line 401, in url_patterns
    patterns = getattr(self.urlconf_module, "urlpatterns", self.urlconf_module)
  File "/usr/local/lib64/python2.7/site-packages/django/core/urlresolvers.py", line 395, in urlconf_module
    self._urlconf_module = import_module(self.urlconf_name)
  File "/usr/lib64/python2.7/importlib/__init__.py", line 37, in import_module
    __import__(name)
  File "/var/www/instag_new/src/instag/urls.py", line 9, in <module>
    import felica.urls
  File "/var/www/instag_new/src/felica/urls.py", line 2, in <module>
    from . import views
  File "/var/www/instag_new/src/felica/views.py", line 14, in <module>
    from .utils import paginator_list
  File "/var/www/instag_new/src/felica/utils.py", line 4, in <module>
    import xlrd
ImportError: No module named xlrd
[21/Apr/2017 17:18:53] ERROR [/usr/local/lib64/python2.7/site-packages/django/core/handlers/base.py:256] Internal Server Error: /favicon.ico
Traceback (most recent call last):
  File "/usr/local/lib64/python2.7/site-packages/django/core/handlers/base.py", line 108, in get_response
    response = middleware_method(request)
  File "/usr/local/lib64/python2.7/site-packages/django/middleware/common.py", line 74, in process_request
    if (not urlresolvers.is_valid_path(request.path_info, urlconf) and
  File "/usr/local/lib64/python2.7/site-packages/django/core/urlresolvers.py", line 646, in is_valid_path
    resolve(path, urlconf)
  File "/usr/local/lib64/python2.7/site-packages/django/core/urlresolvers.py", line 521, in resolve
    return get_resolver(urlconf).resolve(path)
  File "/usr/local/lib64/python2.7/site-packages/django/core/urlresolvers.py", line 365, in resolve
    for pattern in self.url_patterns:
  File "/usr/local/lib64/python2.7/site-packages/django/core/urlresolvers.py", line 401, in url_patterns
    patterns = getattr(self.urlconf_module, "urlpatterns", self.urlconf_module)
  File "/usr/local/lib64/python2.7/site-packages/django/core/urlresolvers.py", line 395, in urlconf_module
    self._urlconf_module = import_module(self.urlconf_name)
  File "/usr/lib64/python2.7/importlib/__init__.py", line 37, in import_module
    __import__(name)
  File "/var/www/instag_new/src/instag/urls.py", line 9, in <module>
    import felica.urls
  File "/var/www/instag_new/src/felica/urls.py", line 2, in <module>
    from . import views
  File "/var/www/instag_new/src/felica/views.py", line 14, in <module>
    from .utils import paginator_list
  File "/var/www/instag_new/src/felica/utils.py", line 4, in <module>
    import xlrd
ImportError: No module named xlrd
[21/Apr/2017 17:18:54] ERROR [/usr/local/lib64/python2.7/site-packages/django/core/handlers/base.py:256] Internal Server Error: /
Traceback (most recent call last):
  File "/usr/local/lib64/python2.7/site-packages/django/core/handlers/base.py", line 119, in get_response
    resolver_match = resolver.resolve(request.path_info)
  File "/usr/local/lib64/python2.7/site-packages/django/core/urlresolvers.py", line 365, in resolve
    for pattern in self.url_patterns:
  File "/usr/local/lib64/python2.7/site-packages/django/core/urlresolvers.py", line 401, in url_patterns
    patterns = getattr(self.urlconf_module, "urlpatterns", self.urlconf_module)
  File "/usr/local/lib64/python2.7/site-packages/django/core/urlresolvers.py", line 395, in urlconf_module
    self._urlconf_module = import_module(self.urlconf_name)
  File "/usr/lib64/python2.7/importlib/__init__.py", line 37, in import_module
    __import__(name)
  File "/var/www/instag_new/src/instag/urls.py", line 9, in <module>
    import felica.urls
  File "/var/www/instag_new/src/felica/urls.py", line 2, in <module>
    from . import views
  File "/var/www/instag_new/src/felica/views.py", line 14, in <module>
    from .utils import paginator_list
  File "/var/www/instag_new/src/felica/utils.py", line 4, in <module>
    import xlrd
ImportError: No module named xlrd
[21/Apr/2017 17:18:54] ERROR [/usr/local/lib64/python2.7/site-packages/django/core/handlers/base.py:256] Internal Server Error: /favicon.ico
Traceback (most recent call last):
  File "/usr/local/lib64/python2.7/site-packages/django/core/handlers/base.py", line 108, in get_response
    response = middleware_method(request)
  File "/usr/local/lib64/python2.7/site-packages/django/middleware/common.py", line 74, in process_request
    if (not urlresolvers.is_valid_path(request.path_info, urlconf) and
  File "/usr/local/lib64/python2.7/site-packages/django/core/urlresolvers.py", line 646, in is_valid_path
    resolve(path, urlconf)
  File "/usr/local/lib64/python2.7/site-packages/django/core/urlresolvers.py", line 521, in resolve
    return get_resolver(urlconf).resolve(path)
  File "/usr/local/lib64/python2.7/site-packages/django/core/urlresolvers.py", line 365, in resolve
    for pattern in self.url_patterns:
  File "/usr/local/lib64/python2.7/site-packages/django/core/urlresolvers.py", line 401, in url_patterns
    patterns = getattr(self.urlconf_module, "urlpatterns", self.urlconf_module)
  File "/usr/local/lib64/python2.7/site-packages/django/core/urlresolvers.py", line 395, in urlconf_module
    self._urlconf_module = import_module(self.urlconf_name)
  File "/usr/lib64/python2.7/importlib/__init__.py", line 37, in import_module
    __import__(name)
  File "/var/www/instag_new/src/instag/urls.py", line 9, in <module>
    import felica.urls
  File "/var/www/instag_new/src/felica/urls.py", line 2, in <module>
    from . import views
  File "/var/www/instag_new/src/felica/views.py", line 14, in <module>
    from .utils import paginator_list
  File "/var/www/instag_new/src/felica/utils.py", line 4, in <module>
    import xlrd
ImportError: No module named xlrd
[21/Apr/2017 17:18:54] ERROR [/usr/local/lib64/python2.7/site-packages/django/core/handlers/base.py:256] Internal Server Error: /
Traceback (most recent call last):
  File "/usr/local/lib64/python2.7/site-packages/django/core/handlers/base.py", line 119, in get_response
    resolver_match = resolver.resolve(request.path_info)
  File "/usr/local/lib64/python2.7/site-packages/django/core/urlresolvers.py", line 365, in resolve
    for pattern in self.url_patterns:
  File "/usr/local/lib64/python2.7/site-packages/django/core/urlresolvers.py", line 401, in url_patterns
    patterns = getattr(self.urlconf_module, "urlpatterns", self.urlconf_module)
  File "/usr/local/lib64/python2.7/site-packages/django/core/urlresolvers.py", line 395, in urlconf_module
    self._urlconf_module = import_module(self.urlconf_name)
  File "/usr/lib64/python2.7/importlib/__init__.py", line 37, in import_module
    __import__(name)
  File "/var/www/instag_new/src/instag/urls.py", line 9, in <module>
    import felica.urls
  File "/var/www/instag_new/src/felica/urls.py", line 2, in <module>
    from . import views
  File "/var/www/instag_new/src/felica/views.py", line 14, in <module>
    from .utils import paginator_list
  File "/var/www/instag_new/src/felica/utils.py", line 4, in <module>
    import xlrd
ImportError: No module named xlrd
[21/Apr/2017 17:18:55] ERROR [/usr/local/lib64/python2.7/site-packages/django/core/handlers/base.py:256] Internal Server Error: /
Traceback (most recent call last):
  File "/usr/local/lib64/python2.7/site-packages/django/core/handlers/base.py", line 119, in get_response
    resolver_match = resolver.resolve(request.path_info)
  File "/usr/local/lib64/python2.7/site-packages/django/core/urlresolvers.py", line 365, in resolve
    for pattern in self.url_patterns:
  File "/usr/local/lib64/python2.7/site-packages/django/core/urlresolvers.py", line 401, in url_patterns
    patterns = getattr(self.urlconf_module, "urlpatterns", self.urlconf_module)
  File "/usr/local/lib64/python2.7/site-packages/django/core/urlresolvers.py", line 395, in urlconf_module
    self._urlconf_module = import_module(self.urlconf_name)
  File "/usr/lib64/python2.7/importlib/__init__.py", line 37, in import_module
    __import__(name)
  File "/var/www/instag_new/src/instag/urls.py", line 9, in <module>
    import felica.urls
  File "/var/www/instag_new/src/felica/urls.py", line 2, in <module>
    from . import views
  File "/var/www/instag_new/src/felica/views.py", line 14, in <module>
    from .utils import paginator_list
  File "/var/www/instag_new/src/felica/utils.py", line 4, in <module>
    import xlrd
ImportError: No module named xlrd
[21/Apr/2017 17:18:56] ERROR [/usr/local/lib64/python2.7/site-packages/django/core/handlers/base.py:256] Internal Server Error: /
Traceback (most recent call last):
  File "/usr/local/lib64/python2.7/site-packages/django/core/handlers/base.py", line 119, in get_response
    resolver_match = resolver.resolve(request.path_info)
  File "/usr/local/lib64/python2.7/site-packages/django/core/urlresolvers.py", line 365, in resolve
    for pattern in self.url_patterns:
  File "/usr/local/lib64/python2.7/site-packages/django/core/urlresolvers.py", line 401, in url_patterns
    patterns = getattr(self.urlconf_module, "urlpatterns", self.urlconf_module)
  File "/usr/local/lib64/python2.7/site-packages/django/core/urlresolvers.py", line 395, in urlconf_module
    self._urlconf_module = import_module(self.urlconf_name)
  File "/usr/lib64/python2.7/importlib/__init__.py", line 37, in import_module
    __import__(name)
  File "/var/www/instag_new/src/instag/urls.py", line 9, in <module>
    import felica.urls
  File "/var/www/instag_new/src/felica/urls.py", line 2, in <module>
    from . import views
  File "/var/www/instag_new/src/felica/views.py", line 14, in <module>
    from .utils import paginator_list
  File "/var/www/instag_new/src/felica/utils.py", line 4, in <module>
    import xlrd
ImportError: No module named xlrd
[21/Apr/2017 17:18:56] ERROR [/usr/local/lib64/python2.7/site-packages/django/core/handlers/base.py:256] Internal Server Error: /
Traceback (most recent call last):
  File "/usr/local/lib64/python2.7/site-packages/django/core/handlers/base.py", line 119, in get_response
    resolver_match = resolver.resolve(request.path_info)
  File "/usr/local/lib64/python2.7/site-packages/django/core/urlresolvers.py", line 365, in resolve
    for pattern in self.url_patterns:
  File "/usr/local/lib64/python2.7/site-packages/django/core/urlresolvers.py", line 401, in url_patterns
    patterns = getattr(self.urlconf_module, "urlpatterns", self.urlconf_module)
  File "/usr/local/lib64/python2.7/site-packages/django/core/urlresolvers.py", line 395, in urlconf_module
    self._urlconf_module = import_module(self.urlconf_name)
  File "/usr/lib64/python2.7/importlib/__init__.py", line 37, in import_module
    __import__(name)
  File "/var/www/instag_new/src/instag/urls.py", line 9, in <module>
    import felica.urls
  File "/var/www/instag_new/src/felica/urls.py", line 2, in <module>
    from . import views
  File "/var/www/instag_new/src/felica/views.py", line 14, in <module>
    from .utils import paginator_list
  File "/var/www/instag_new/src/felica/utils.py", line 4, in <module>
    import xlrd
ImportError: No module named xlrd
[21/Apr/2017 17:18:56] ERROR [/usr/local/lib64/python2.7/site-packages/django/core/handlers/base.py:256] Internal Server Error: /favicon.ico
Traceback (most recent call last):
  File "/usr/local/lib64/python2.7/site-packages/django/core/handlers/base.py", line 108, in get_response
    response = middleware_method(request)
  File "/usr/local/lib64/python2.7/site-packages/django/middleware/common.py", line 74, in process_request
    if (not urlresolvers.is_valid_path(request.path_info, urlconf) and
  File "/usr/local/lib64/python2.7/site-packages/django/core/urlresolvers.py", line 646, in is_valid_path
    resolve(path, urlconf)
  File "/usr/local/lib64/python2.7/site-packages/django/core/urlresolvers.py", line 521, in resolve
    return get_resolver(urlconf).resolve(path)
  File "/usr/local/lib64/python2.7/site-packages/django/core/urlresolvers.py", line 365, in resolve
    for pattern in self.url_patterns:
  File "/usr/local/lib64/python2.7/site-packages/django/core/urlresolvers.py", line 401, in url_patterns
    patterns = getattr(self.urlconf_module, "urlpatterns", self.urlconf_module)
  File "/usr/local/lib64/python2.7/site-packages/django/core/urlresolvers.py", line 395, in urlconf_module
    self._urlconf_module = import_module(self.urlconf_name)
  File "/usr/lib64/python2.7/importlib/__init__.py", line 37, in import_module
    __import__(name)
  File "/var/www/instag_new/src/instag/urls.py", line 9, in <module>
    import felica.urls
  File "/var/www/instag_new/src/felica/urls.py", line 2, in <module>
    from . import views
  File "/var/www/instag_new/src/felica/views.py", line 14, in <module>
    from .utils import paginator_list
  File "/var/www/instag_new/src/felica/utils.py", line 4, in <module>
    import xlrd
ImportError: No module named xlrd
[21/Apr/2017 17:19:09] ERROR [/usr/local/lib64/python2.7/site-packages/django/core/handlers/base.py:256] Internal Server Error: /
Traceback (most recent call last):
  File "/usr/local/lib64/python2.7/site-packages/django/core/handlers/base.py", line 119, in get_response
    resolver_match = resolver.resolve(request.path_info)
  File "/usr/local/lib64/python2.7/site-packages/django/core/urlresolvers.py", line 365, in resolve
    for pattern in self.url_patterns:
  File "/usr/local/lib64/python2.7/site-packages/django/core/urlresolvers.py", line 401, in url_patterns
    patterns = getattr(self.urlconf_module, "urlpatterns", self.urlconf_module)
  File "/usr/local/lib64/python2.7/site-packages/django/core/urlresolvers.py", line 395, in urlconf_module
    self._urlconf_module = import_module(self.urlconf_name)
  File "/usr/lib64/python2.7/importlib/__init__.py", line 37, in import_module
    __import__(name)
  File "/var/www/instag_new/src/instag/urls.py", line 9, in <module>
    import felica.urls
  File "/var/www/instag_new/src/felica/urls.py", line 2, in <module>
    from . import views
  File "/var/www/instag_new/src/felica/views.py", line 14, in <module>
    from .utils import paginator_list
  File "/var/www/instag_new/src/felica/utils.py", line 4, in <module>
    import xlrd
ImportError: No module named xlrd
[21/Apr/2017 17:19:09] ERROR [/usr/local/lib64/python2.7/site-packages/django/core/handlers/base.py:256] Internal Server Error: /favicon.ico
Traceback (most recent call last):
  File "/usr/local/lib64/python2.7/site-packages/django/core/handlers/base.py", line 108, in get_response
    response = middleware_method(request)
  File "/usr/local/lib64/python2.7/site-packages/django/middleware/common.py", line 74, in process_request
    if (not urlresolvers.is_valid_path(request.path_info, urlconf) and
  File "/usr/local/lib64/python2.7/site-packages/django/core/urlresolvers.py", line 646, in is_valid_path
    resolve(path, urlconf)
  File "/usr/local/lib64/python2.7/site-packages/django/core/urlresolvers.py", line 521, in resolve
    return get_resolver(urlconf).resolve(path)
  File "/usr/local/lib64/python2.7/site-packages/django/core/urlresolvers.py", line 365, in resolve
    for pattern in self.url_patterns:
  File "/usr/local/lib64/python2.7/site-packages/django/core/urlresolvers.py", line 401, in url_patterns
    patterns = getattr(self.urlconf_module, "urlpatterns", self.urlconf_module)
  File "/usr/local/lib64/python2.7/site-packages/django/core/urlresolvers.py", line 395, in urlconf_module
    self._urlconf_module = import_module(self.urlconf_name)
  File "/usr/lib64/python2.7/importlib/__init__.py", line 37, in import_module
    __import__(name)
  File "/var/www/instag_new/src/instag/urls.py", line 9, in <module>
    import felica.urls
  File "/var/www/instag_new/src/felica/urls.py", line 2, in <module>
    from . import views
  File "/var/www/instag_new/src/felica/views.py", line 14, in <module>
    from .utils import paginator_list
  File "/var/www/instag_new/src/felica/utils.py", line 4, in <module>
    import xlrd
ImportError: No module named xlrd
[21/Apr/2017 17:19:11] ERROR [/usr/local/lib64/python2.7/site-packages/django/core/handlers/base.py:256] Internal Server Error: /
Traceback (most recent call last):
  File "/usr/local/lib64/python2.7/site-packages/django/core/handlers/base.py", line 119, in get_response
    resolver_match = resolver.resolve(request.path_info)
  File "/usr/local/lib64/python2.7/site-packages/django/core/urlresolvers.py", line 365, in resolve
    for pattern in self.url_patterns:
  File "/usr/local/lib64/python2.7/site-packages/django/core/urlresolvers.py", line 401, in url_patterns
    patterns = getattr(self.urlconf_module, "urlpatterns", self.urlconf_module)
  File "/usr/local/lib64/python2.7/site-packages/django/core/urlresolvers.py", line 395, in urlconf_module
    self._urlconf_module = import_module(self.urlconf_name)
  File "/usr/lib64/python2.7/importlib/__init__.py", line 37, in import_module
    __import__(name)
  File "/var/www/instag_new/src/instag/urls.py", line 9, in <module>
    import felica.urls
  File "/var/www/instag_new/src/felica/urls.py", line 2, in <module>
    from . import views
  File "/var/www/instag_new/src/felica/views.py", line 14, in <module>
    from .utils import paginator_list
  File "/var/www/instag_new/src/felica/utils.py", line 4, in <module>
    import xlrd
ImportError: No module named xlrd
[21/Apr/2017 17:19:11] ERROR [/usr/local/lib64/python2.7/site-packages/django/core/handlers/base.py:256] Internal Server Error: /favicon.ico
Traceback (most recent call last):
  File "/usr/local/lib64/python2.7/site-packages/django/core/handlers/base.py", line 108, in get_response
    response = middleware_method(request)
  File "/usr/local/lib64/python2.7/site-packages/django/middleware/common.py", line 74, in process_request
    if (not urlresolvers.is_valid_path(request.path_info, urlconf) and
  File "/usr/local/lib64/python2.7/site-packages/django/core/urlresolvers.py", line 646, in is_valid_path
    resolve(path, urlconf)
  File "/usr/local/lib64/python2.7/site-packages/django/core/urlresolvers.py", line 521, in resolve
    return get_resolver(urlconf).resolve(path)
  File "/usr/local/lib64/python2.7/site-packages/django/core/urlresolvers.py", line 365, in resolve
    for pattern in self.url_patterns:
  File "/usr/local/lib64/python2.7/site-packages/django/core/urlresolvers.py", line 401, in url_patterns
    patterns = getattr(self.urlconf_module, "urlpatterns", self.urlconf_module)
  File "/usr/local/lib64/python2.7/site-packages/django/core/urlresolvers.py", line 395, in urlconf_module
    self._urlconf_module = import_module(self.urlconf_name)
  File "/usr/lib64/python2.7/importlib/__init__.py", line 37, in import_module
    __import__(name)
  File "/var/www/instag_new/src/instag/urls.py", line 9, in <module>
    import felica.urls
  File "/var/www/instag_new/src/felica/urls.py", line 2, in <module>
    from . import views
  File "/var/www/instag_new/src/felica/views.py", line 14, in <module>
    from .utils import paginator_list
  File "/var/www/instag_new/src/felica/utils.py", line 4, in <module>
    import xlrd
ImportError: No module named xlrd
[21/Apr/2017 17:23:20] ERROR [/usr/local/lib64/python2.7/site-packages/django/core/handlers/base.py:256] Internal Server Error: /
Traceback (most recent call last):
  File "/usr/local/lib64/python2.7/site-packages/django/core/handlers/base.py", line 119, in get_response
    resolver_match = resolver.resolve(request.path_info)
  File "/usr/local/lib64/python2.7/site-packages/django/core/urlresolvers.py", line 365, in resolve
    for pattern in self.url_patterns:
  File "/usr/local/lib64/python2.7/site-packages/django/core/urlresolvers.py", line 401, in url_patterns
    patterns = getattr(self.urlconf_module, "urlpatterns", self.urlconf_module)
  File "/usr/local/lib64/python2.7/site-packages/django/core/urlresolvers.py", line 395, in urlconf_module
    self._urlconf_module = import_module(self.urlconf_name)
  File "/usr/lib64/python2.7/importlib/__init__.py", line 37, in import_module
    __import__(name)
  File "/var/www/instag_new/src/instag/urls.py", line 9, in <module>
    import felica.urls
  File "/var/www/instag_new/src/felica/urls.py", line 2, in <module>
    from . import views
  File "/var/www/instag_new/src/felica/views.py", line 14, in <module>
    from .utils import paginator_list
  File "/var/www/instag_new/src/felica/utils.py", line 4, in <module>
    import xlrd
ImportError: No module named xlrd
[21/Apr/2017 17:23:21] ERROR [/usr/local/lib64/python2.7/site-packages/django/core/handlers/base.py:256] Internal Server Error: /favicon.ico
Traceback (most recent call last):
  File "/usr/local/lib64/python2.7/site-packages/django/core/handlers/base.py", line 108, in get_response
    response = middleware_method(request)
  File "/usr/local/lib64/python2.7/site-packages/django/middleware/common.py", line 74, in process_request
    if (not urlresolvers.is_valid_path(request.path_info, urlconf) and
  File "/usr/local/lib64/python2.7/site-packages/django/core/urlresolvers.py", line 646, in is_valid_path
    resolve(path, urlconf)
  File "/usr/local/lib64/python2.7/site-packages/django/core/urlresolvers.py", line 521, in resolve
    return get_resolver(urlconf).resolve(path)
  File "/usr/local/lib64/python2.7/site-packages/django/core/urlresolvers.py", line 365, in resolve
    for pattern in self.url_patterns:
  File "/usr/local/lib64/python2.7/site-packages/django/core/urlresolvers.py", line 401, in url_patterns
    patterns = getattr(self.urlconf_module, "urlpatterns", self.urlconf_module)
  File "/usr/local/lib64/python2.7/site-packages/django/core/urlresolvers.py", line 395, in urlconf_module
    self._urlconf_module = import_module(self.urlconf_name)
  File "/usr/lib64/python2.7/importlib/__init__.py", line 37, in import_module
    __import__(name)
  File "/var/www/instag_new/src/instag/urls.py", line 9, in <module>
    import felica.urls
  File "/var/www/instag_new/src/felica/urls.py", line 2, in <module>
    from . import views
  File "/var/www/instag_new/src/felica/views.py", line 14, in <module>
    from .utils import paginator_list
  File "/var/www/instag_new/src/felica/utils.py", line 4, in <module>
    import xlrd
ImportError: No module named xlrd
[21/Apr/2017 17:23:23] ERROR [/usr/local/lib64/python2.7/site-packages/django/core/handlers/base.py:256] Internal Server Error: /
Traceback (most recent call last):
  File "/usr/local/lib64/python2.7/site-packages/django/core/handlers/base.py", line 119, in get_response
    resolver_match = resolver.resolve(request.path_info)
  File "/usr/local/lib64/python2.7/site-packages/django/core/urlresolvers.py", line 365, in resolve
    for pattern in self.url_patterns:
  File "/usr/local/lib64/python2.7/site-packages/django/core/urlresolvers.py", line 401, in url_patterns
    patterns = getattr(self.urlconf_module, "urlpatterns", self.urlconf_module)
  File "/usr/local/lib64/python2.7/site-packages/django/core/urlresolvers.py", line 395, in urlconf_module
    self._urlconf_module = import_module(self.urlconf_name)
  File "/usr/lib64/python2.7/importlib/__init__.py", line 37, in import_module
    __import__(name)
  File "/var/www/instag_new/src/instag/urls.py", line 9, in <module>
    import felica.urls
  File "/var/www/instag_new/src/felica/urls.py", line 2, in <module>
    from . import views
  File "/var/www/instag_new/src/felica/views.py", line 14, in <module>
    from .utils import paginator_list
  File "/var/www/instag_new/src/felica/utils.py", line 4, in <module>
    import xlrd
ImportError: No module named xlrd
[21/Apr/2017 17:23:24] ERROR [/usr/local/lib64/python2.7/site-packages/django/core/handlers/base.py:256] Internal Server Error: /
Traceback (most recent call last):
  File "/usr/local/lib64/python2.7/site-packages/django/core/handlers/base.py", line 119, in get_response
    resolver_match = resolver.resolve(request.path_info)
  File "/usr/local/lib64/python2.7/site-packages/django/core/urlresolvers.py", line 365, in resolve
    for pattern in self.url_patterns:
  File "/usr/local/lib64/python2.7/site-packages/django/core/urlresolvers.py", line 401, in url_patterns
    patterns = getattr(self.urlconf_module, "urlpatterns", self.urlconf_module)
  File "/usr/local/lib64/python2.7/site-packages/django/core/urlresolvers.py", line 395, in urlconf_module
    self._urlconf_module = import_module(self.urlconf_name)
  File "/usr/lib64/python2.7/importlib/__init__.py", line 37, in import_module
    __import__(name)
  File "/var/www/instag_new/src/instag/urls.py", line 9, in <module>
    import felica.urls
  File "/var/www/instag_new/src/felica/urls.py", line 2, in <module>
    from . import views
  File "/var/www/instag_new/src/felica/views.py", line 14, in <module>
    from .utils import paginator_list
  File "/var/www/instag_new/src/felica/utils.py", line 4, in <module>
    import xlrd
ImportError: No module named xlrd
[21/Apr/2017 17:23:24] ERROR [/usr/local/lib64/python2.7/site-packages/django/core/handlers/base.py:256] Internal Server Error: /
Traceback (most recent call last):
  File "/usr/local/lib64/python2.7/site-packages/django/core/handlers/base.py", line 119, in get_response
    resolver_match = resolver.resolve(request.path_info)
  File "/usr/local/lib64/python2.7/site-packages/django/core/urlresolvers.py", line 365, in resolve
    for pattern in self.url_patterns:
  File "/usr/local/lib64/python2.7/site-packages/django/core/urlresolvers.py", line 401, in url_patterns
    patterns = getattr(self.urlconf_module, "urlpatterns", self.urlconf_module)
  File "/usr/local/lib64/python2.7/site-packages/django/core/urlresolvers.py", line 395, in urlconf_module
    self._urlconf_module = import_module(self.urlconf_name)
  File "/usr/lib64/python2.7/importlib/__init__.py", line 37, in import_module
    __import__(name)
  File "/var/www/instag_new/src/instag/urls.py", line 9, in <module>
    import felica.urls
  File "/var/www/instag_new/src/felica/urls.py", line 2, in <module>
    from . import views
  File "/var/www/instag_new/src/felica/views.py", line 14, in <module>
    from .utils import paginator_list
  File "/var/www/instag_new/src/felica/utils.py", line 4, in <module>
    import xlrd
ImportError: No module named xlrd
[21/Apr/2017 17:23:24] ERROR [/usr/local/lib64/python2.7/site-packages/django/core/handlers/base.py:256] Internal Server Error: /
Traceback (most recent call last):
  File "/usr/local/lib64/python2.7/site-packages/django/core/handlers/base.py", line 119, in get_response
    resolver_match = resolver.resolve(request.path_info)
  File "/usr/local/lib64/python2.7/site-packages/django/core/urlresolvers.py", line 365, in resolve
    for pattern in self.url_patterns:
  File "/usr/local/lib64/python2.7/site-packages/django/core/urlresolvers.py", line 401, in url_patterns
    patterns = getattr(self.urlconf_module, "urlpatterns", self.urlconf_module)
  File "/usr/local/lib64/python2.7/site-packages/django/core/urlresolvers.py", line 395, in urlconf_module
    self._urlconf_module = import_module(self.urlconf_name)
  File "/usr/lib64/python2.7/importlib/__init__.py", line 37, in import_module
    __import__(name)
  File "/var/www/instag_new/src/instag/urls.py", line 9, in <module>
    import felica.urls
  File "/var/www/instag_new/src/felica/urls.py", line 2, in <module>
    from . import views
  File "/var/www/instag_new/src/felica/views.py", line 14, in <module>
    from .utils import paginator_list
  File "/var/www/instag_new/src/felica/utils.py", line 4, in <module>
    import xlrd
ImportError: No module named xlrd
[21/Apr/2017 17:23:24] ERROR [/usr/local/lib64/python2.7/site-packages/django/core/handlers/base.py:256] Internal Server Error: /
Traceback (most recent call last):
  File "/usr/local/lib64/python2.7/site-packages/django/core/handlers/base.py", line 119, in get_response
    resolver_match = resolver.resolve(request.path_info)
  File "/usr/local/lib64/python2.7/site-packages/django/core/urlresolvers.py", line 365, in resolve
    for pattern in self.url_patterns:
  File "/usr/local/lib64/python2.7/site-packages/django/core/urlresolvers.py", line 401, in url_patterns
    patterns = getattr(self.urlconf_module, "urlpatterns", self.urlconf_module)
  File "/usr/local/lib64/python2.7/site-packages/django/core/urlresolvers.py", line 395, in urlconf_module
    self._urlconf_module = import_module(self.urlconf_name)
  File "/usr/lib64/python2.7/importlib/__init__.py", line 37, in import_module
    __import__(name)
  File "/var/www/instag_new/src/instag/urls.py", line 9, in <module>
    import felica.urls
  File "/var/www/instag_new/src/felica/urls.py", line 2, in <module>
    from . import views
  File "/var/www/instag_new/src/felica/views.py", line 14, in <module>
    from .utils import paginator_list
  File "/var/www/instag_new/src/felica/utils.py", line 4, in <module>
    import xlrd
ImportError: No module named xlrd
[21/Apr/2017 17:23:25] ERROR [/usr/local/lib64/python2.7/site-packages/django/core/handlers/base.py:256] Internal Server Error: /favicon.ico
Traceback (most recent call last):
  File "/usr/local/lib64/python2.7/site-packages/django/core/handlers/base.py", line 108, in get_response
    response = middleware_method(request)
  File "/usr/local/lib64/python2.7/site-packages/django/middleware/common.py", line 74, in process_request
    if (not urlresolvers.is_valid_path(request.path_info, urlconf) and
  File "/usr/local/lib64/python2.7/site-packages/django/core/urlresolvers.py", line 646, in is_valid_path
    resolve(path, urlconf)
  File "/usr/local/lib64/python2.7/site-packages/django/core/urlresolvers.py", line 521, in resolve
    return get_resolver(urlconf).resolve(path)
  File "/usr/local/lib64/python2.7/site-packages/django/core/urlresolvers.py", line 365, in resolve
    for pattern in self.url_patterns:
  File "/usr/local/lib64/python2.7/site-packages/django/core/urlresolvers.py", line 401, in url_patterns
    patterns = getattr(self.urlconf_module, "urlpatterns", self.urlconf_module)
  File "/usr/local/lib64/python2.7/site-packages/django/core/urlresolvers.py", line 395, in urlconf_module
    self._urlconf_module = import_module(self.urlconf_name)
  File "/usr/lib64/python2.7/importlib/__init__.py", line 37, in import_module
    __import__(name)
  File "/var/www/instag_new/src/instag/urls.py", line 9, in <module>
    import felica.urls
  File "/var/www/instag_new/src/felica/urls.py", line 2, in <module>
    from . import views
  File "/var/www/instag_new/src/felica/views.py", line 14, in <module>
    from .utils import paginator_list
  File "/var/www/instag_new/src/felica/utils.py", line 4, in <module>
    import xlrd
ImportError: No module named xlrd
[21/Apr/2017 17:23:42] ERROR [/usr/local/lib64/python2.7/site-packages/django/core/handlers/base.py:256] Internal Server Error: /
Traceback (most recent call last):
  File "/usr/local/lib64/python2.7/site-packages/django/core/handlers/base.py", line 119, in get_response
    resolver_match = resolver.resolve(request.path_info)
  File "/usr/local/lib64/python2.7/site-packages/django/core/urlresolvers.py", line 365, in resolve
    for pattern in self.url_patterns:
  File "/usr/local/lib64/python2.7/site-packages/django/core/urlresolvers.py", line 401, in url_patterns
    patterns = getattr(self.urlconf_module, "urlpatterns", self.urlconf_module)
  File "/usr/local/lib64/python2.7/site-packages/django/core/urlresolvers.py", line 395, in urlconf_module
    self._urlconf_module = import_module(self.urlconf_name)
  File "/usr/lib64/python2.7/importlib/__init__.py", line 37, in import_module
    __import__(name)
  File "/var/www/instag_new/src/instag/urls.py", line 9, in <module>
    import felica.urls
  File "/var/www/instag_new/src/felica/urls.py", line 2, in <module>
    from . import views
  File "/var/www/instag_new/src/felica/views.py", line 14, in <module>
    from .utils import paginator_list
  File "/var/www/instag_new/src/felica/utils.py", line 4, in <module>
    import xlrd
ImportError: No module named xlrd
[21/Apr/2017 17:23:42] ERROR [/usr/local/lib64/python2.7/site-packages/django/core/handlers/base.py:256] Internal Server Error: /favicon.ico
Traceback (most recent call last):
  File "/usr/local/lib64/python2.7/site-packages/django/core/handlers/base.py", line 108, in get_response
    response = middleware_method(request)
  File "/usr/local/lib64/python2.7/site-packages/django/middleware/common.py", line 74, in process_request
    if (not urlresolvers.is_valid_path(request.path_info, urlconf) and
  File "/usr/local/lib64/python2.7/site-packages/django/core/urlresolvers.py", line 646, in is_valid_path
    resolve(path, urlconf)
  File "/usr/local/lib64/python2.7/site-packages/django/core/urlresolvers.py", line 521, in resolve
    return get_resolver(urlconf).resolve(path)
  File "/usr/local/lib64/python2.7/site-packages/django/core/urlresolvers.py", line 365, in resolve
    for pattern in self.url_patterns:
  File "/usr/local/lib64/python2.7/site-packages/django/core/urlresolvers.py", line 401, in url_patterns
    patterns = getattr(self.urlconf_module, "urlpatterns", self.urlconf_module)
  File "/usr/local/lib64/python2.7/site-packages/django/core/urlresolvers.py", line 395, in urlconf_module
    self._urlconf_module = import_module(self.urlconf_name)
  File "/usr/lib64/python2.7/importlib/__init__.py", line 37, in import_module
    __import__(name)
  File "/var/www/instag_new/src/instag/urls.py", line 9, in <module>
    import felica.urls
  File "/var/www/instag_new/src/felica/urls.py", line 2, in <module>
    from . import views
  File "/var/www/instag_new/src/felica/views.py", line 14, in <module>
    from .utils import paginator_list
  File "/var/www/instag_new/src/felica/utils.py", line 4, in <module>
    import xlrd
ImportError: No module named xlrd
[21/Apr/2017 17:32:29] ERROR [/usr/local/lib64/python2.7/site-packages/django/core/handlers/base.py:256] Internal Server Error: /felica/
Traceback (most recent call last):
  File "/usr/local/lib64/python2.7/site-packages/django/core/handlers/base.py", line 151, in get_response
    % (callback.__module__, view_name))
ValueError: The view felica.views.Felica didn't return an HttpResponse object. It returned None instead.
[21/Apr/2017 17:44:01] ERROR [/usr/local/lib64/python2.7/site-packages/django/core/handlers/base.py:256] Internal Server Error: /felica/felica/time/edit/1
Traceback (most recent call last):
  File "/usr/local/lib64/python2.7/site-packages/django/core/handlers/base.py", line 132, in get_response
    response = wrapped_callback(request, *callback_args, **callback_kwargs)
  File "/usr/local/lib64/python2.7/site-packages/django/views/generic/base.py", line 71, in view
    return self.dispatch(request, *args, **kwargs)
  File "/usr/local/lib/python2.7/site-packages/braces/views/_access.py", line 98, in dispatch
    request, *args, **kwargs)
  File "/usr/local/lib64/python2.7/site-packages/django/views/generic/base.py", line 89, in dispatch
    return handler(request, *args, **kwargs)
  File "/var/www/instag_new/src/felica/views.py", line 129, in post
    result = FelicaTime.update(user.id, request.POST, kwargs['id'])
  File "/var/www/instag_new/src/felica/models.py", line 110, in update
    result.save()
  File "/usr/local/lib64/python2.7/site-packages/django/db/models/base.py", line 734, in save
    force_update=force_update, update_fields=update_fields)
  File "/usr/local/lib64/python2.7/site-packages/django/db/models/base.py", line 762, in save_base
    updated = self._save_table(raw, cls, force_insert, force_update, using, update_fields)
  File "/usr/local/lib64/python2.7/site-packages/django/db/models/base.py", line 827, in _save_table
    forced_update)
  File "/usr/local/lib64/python2.7/site-packages/django/db/models/base.py", line 877, in _do_update
    return filtered._update(values) > 0
  File "/usr/local/lib64/python2.7/site-packages/django/db/models/query.py", line 580, in _update
    return query.get_compiler(self.db).execute_sql(CURSOR)
  File "/usr/local/lib64/python2.7/site-packages/django/db/models/sql/compiler.py", line 1062, in execute_sql
    cursor = super(SQLUpdateCompiler, self).execute_sql(result_type)
  File "/usr/local/lib64/python2.7/site-packages/django/db/models/sql/compiler.py", line 829, in execute_sql
    sql, params = self.as_sql()
  File "/usr/local/lib64/python2.7/site-packages/django/db/models/sql/compiler.py", line 1030, in as_sql
    val = field.get_db_prep_save(val, connection=self.connection)
  File "/usr/local/lib64/python2.7/site-packages/django/db/models/fields/__init__.py", line 710, in get_db_prep_save
    prepared=False)
  File "/usr/local/lib64/python2.7/site-packages/django/db/models/fields/__init__.py", line 1482, in get_db_prep_value
    value = self.get_prep_value(value)
  File "/usr/local/lib64/python2.7/site-packages/django/db/models/fields/__init__.py", line 1461, in get_prep_value
    value = super(DateTimeField, self).get_prep_value(value)
  File "/usr/local/lib64/python2.7/site-packages/django/db/models/fields/__init__.py", line 1317, in get_prep_value
    return self.to_python(value)
  File "/usr/local/lib64/python2.7/site-packages/django/db/models/fields/__init__.py", line 1444, in to_python
    params={'value': value},
ValidationError: [u"'' \u306f\u7121\u52b9\u306a\u5f62\u5f0f\u306e\u5024\u3067\u3059\u3002 YYYY-MM-DD HH:MM[:ss[.uuuuuu]][TZ] \u5f62\u5f0f\u3067\u306a\u3051\u308c\u3070\u306a\u308a\u307e\u305b\u3093\u3002"]
[21/Apr/2017 17:45:14] ERROR [/usr/local/lib64/python2.7/site-packages/django/core/handlers/base.py:256] Internal Server Error: /felica/felica/time/edit/1
Traceback (most recent call last):
  File "/usr/local/lib64/python2.7/site-packages/django/core/handlers/base.py", line 132, in get_response
    response = wrapped_callback(request, *callback_args, **callback_kwargs)
  File "/usr/local/lib64/python2.7/site-packages/django/views/generic/base.py", line 71, in view
    return self.dispatch(request, *args, **kwargs)
  File "/usr/local/lib/python2.7/site-packages/braces/views/_access.py", line 98, in dispatch
    request, *args, **kwargs)
  File "/usr/local/lib64/python2.7/site-packages/django/views/generic/base.py", line 89, in dispatch
    return handler(request, *args, **kwargs)
  File "/var/www/instag_new/src/felica/views.py", line 129, in post
    result = FelicaTime.update(user.id, request.POST, kwargs['id'])
  File "/var/www/instag_new/src/felica/models.py", line 110, in update
    result.save()
  File "/usr/local/lib64/python2.7/site-packages/django/db/models/base.py", line 734, in save
    force_update=force_update, update_fields=update_fields)
  File "/usr/local/lib64/python2.7/site-packages/django/db/models/base.py", line 762, in save_base
    updated = self._save_table(raw, cls, force_insert, force_update, using, update_fields)
  File "/usr/local/lib64/python2.7/site-packages/django/db/models/base.py", line 827, in _save_table
    forced_update)
  File "/usr/local/lib64/python2.7/site-packages/django/db/models/base.py", line 877, in _do_update
    return filtered._update(values) > 0
  File "/usr/local/lib64/python2.7/site-packages/django/db/models/query.py", line 580, in _update
    return query.get_compiler(self.db).execute_sql(CURSOR)
  File "/usr/local/lib64/python2.7/site-packages/django/db/models/sql/compiler.py", line 1062, in execute_sql
    cursor = super(SQLUpdateCompiler, self).execute_sql(result_type)
  File "/usr/local/lib64/python2.7/site-packages/django/db/models/sql/compiler.py", line 829, in execute_sql
    sql, params = self.as_sql()
  File "/usr/local/lib64/python2.7/site-packages/django/db/models/sql/compiler.py", line 1030, in as_sql
    val = field.get_db_prep_save(val, connection=self.connection)
  File "/usr/local/lib64/python2.7/site-packages/django/db/models/fields/__init__.py", line 710, in get_db_prep_save
    prepared=False)
  File "/usr/local/lib64/python2.7/site-packages/django/db/models/fields/__init__.py", line 1482, in get_db_prep_value
    value = self.get_prep_value(value)
  File "/usr/local/lib64/python2.7/site-packages/django/db/models/fields/__init__.py", line 1461, in get_prep_value
    value = super(DateTimeField, self).get_prep_value(value)
  File "/usr/local/lib64/python2.7/site-packages/django/db/models/fields/__init__.py", line 1317, in get_prep_value
    return self.to_python(value)
  File "/usr/local/lib64/python2.7/site-packages/django/db/models/fields/__init__.py", line 1444, in to_python
    params={'value': value},
ValidationError: [u"'' \u306f\u7121\u52b9\u306a\u5f62\u5f0f\u306e\u5024\u3067\u3059\u3002 YYYY-MM-DD HH:MM[:ss[.uuuuuu]][TZ] \u5f62\u5f0f\u3067\u306a\u3051\u308c\u3070\u306a\u308a\u307e\u305b\u3093\u3002"]
[21/Apr/2017 17:45:18] ERROR [/usr/local/lib64/python2.7/site-packages/django/core/handlers/base.py:256] Internal Server Error: /felica/felica/time/edit/1
Traceback (most recent call last):
  File "/usr/local/lib64/python2.7/site-packages/django/core/handlers/base.py", line 132, in get_response
    response = wrapped_callback(request, *callback_args, **callback_kwargs)
  File "/usr/local/lib64/python2.7/site-packages/django/views/generic/base.py", line 71, in view
    return self.dispatch(request, *args, **kwargs)
  File "/usr/local/lib/python2.7/site-packages/braces/views/_access.py", line 98, in dispatch
    request, *args, **kwargs)
  File "/usr/local/lib64/python2.7/site-packages/django/views/generic/base.py", line 89, in dispatch
    return handler(request, *args, **kwargs)
  File "/var/www/instag_new/src/felica/views.py", line 129, in post
    result = FelicaTime.update(user.id, request.POST, kwargs['id'])
  File "/var/www/instag_new/src/felica/models.py", line 110, in update
    result.save()
  File "/usr/local/lib64/python2.7/site-packages/django/db/models/base.py", line 734, in save
    force_update=force_update, update_fields=update_fields)
  File "/usr/local/lib64/python2.7/site-packages/django/db/models/base.py", line 762, in save_base
    updated = self._save_table(raw, cls, force_insert, force_update, using, update_fields)
  File "/usr/local/lib64/python2.7/site-packages/django/db/models/base.py", line 827, in _save_table
    forced_update)
  File "/usr/local/lib64/python2.7/site-packages/django/db/models/base.py", line 877, in _do_update
    return filtered._update(values) > 0
  File "/usr/local/lib64/python2.7/site-packages/django/db/models/query.py", line 580, in _update
    return query.get_compiler(self.db).execute_sql(CURSOR)
  File "/usr/local/lib64/python2.7/site-packages/django/db/models/sql/compiler.py", line 1062, in execute_sql
    cursor = super(SQLUpdateCompiler, self).execute_sql(result_type)
  File "/usr/local/lib64/python2.7/site-packages/django/db/models/sql/compiler.py", line 829, in execute_sql
    sql, params = self.as_sql()
  File "/usr/local/lib64/python2.7/site-packages/django/db/models/sql/compiler.py", line 1030, in as_sql
    val = field.get_db_prep_save(val, connection=self.connection)
  File "/usr/local/lib64/python2.7/site-packages/django/db/models/fields/__init__.py", line 710, in get_db_prep_save
    prepared=False)
  File "/usr/local/lib64/python2.7/site-packages/django/db/models/fields/__init__.py", line 1482, in get_db_prep_value
    value = self.get_prep_value(value)
  File "/usr/local/lib64/python2.7/site-packages/django/db/models/fields/__init__.py", line 1461, in get_prep_value
    value = super(DateTimeField, self).get_prep_value(value)
  File "/usr/local/lib64/python2.7/site-packages/django/db/models/fields/__init__.py", line 1317, in get_prep_value
    return self.to_python(value)
  File "/usr/local/lib64/python2.7/site-packages/django/db/models/fields/__init__.py", line 1444, in to_python
    params={'value': value},
ValidationError: [u"'0' \u306f\u7121\u52b9\u306a\u5f62\u5f0f\u306e\u5024\u3067\u3059\u3002 YYYY-MM-DD HH:MM[:ss[.uuuuuu]][TZ] \u5f62\u5f0f\u3067\u306a\u3051\u308c\u3070\u306a\u308a\u307e\u305b\u3093\u3002"]
[21/Apr/2017 17:52:20] ERROR [/usr/local/lib64/python2.7/site-packages/django/core/handlers/base.py:256] Internal Server Error: /felica/
Traceback (most recent call last):
  File "/usr/local/lib64/python2.7/site-packages/django/core/handlers/base.py", line 132, in get_response
    response = wrapped_callback(request, *callback_args, **callback_kwargs)
  File "/usr/local/lib64/python2.7/site-packages/django/views/generic/base.py", line 71, in view
    return self.dispatch(request, *args, **kwargs)
  File "/usr/local/lib64/python2.7/site-packages/django/views/generic/base.py", line 89, in dispatch
    return handler(request, *args, **kwargs)
  File "/var/www/instag_new/src/felica/views.py", line 46, in get
    fm.member_name
  File "/var/www/instag_new/src/felica/models.py", line 84, in set_work_time
    return result
UnboundLocalError: local variable 'result' referenced before assignment
[24/Apr/2017 18:44:03] ERROR [/usr/local/lib64/python2.7/site-packages/django/core/handlers/base.py:256] Internal Server Error: /twitter_count/realtime_ko/
Traceback (most recent call last):
  File "/usr/local/lib64/python2.7/site-packages/django/core/handlers/base.py", line 132, in get_response
    response = wrapped_callback(request, *callback_args, **callback_kwargs)
  File "/usr/local/lib64/python2.7/site-packages/django/views/generic/base.py", line 71, in view
    return self.dispatch(request, *args, **kwargs)
  File "/usr/local/lib64/python2.7/site-packages/django/views/generic/base.py", line 89, in dispatch
    return handler(request, *args, **kwargs)
  File "/var/www/instag_new/src/twitter_count/views.py", line 81, in get
    twitter_ranking_list = twitter_ranking_list[int(url_from)-1:url_to]
ValueError: invalid literal for int() with base 10: ''
[24/Apr/2017 23:40:36] ERROR [/usr/local/lib64/python2.7/site-packages/django/core/handlers/base.py:256] Internal Server Error: /twitter_count/realtime_jp/
Traceback (most recent call last):
  File "/usr/local/lib64/python2.7/site-packages/django/core/handlers/base.py", line 132, in get_response
    response = wrapped_callback(request, *callback_args, **callback_kwargs)
  File "/usr/local/lib64/python2.7/site-packages/django/views/generic/base.py", line 71, in view
    return self.dispatch(request, *args, **kwargs)
  File "/usr/local/lib64/python2.7/site-packages/django/views/generic/base.py", line 89, in dispatch
    return handler(request, *args, **kwargs)
  File "/var/www/instag_new/src/twitter_count/views.py", line 50, in get
    twitter_ranking_list = twitter_ranking_list[int(url_from)-1:url_to]
ValueError: invalid literal for int() with base 10: ''
[26/Apr/2017 14:10:04] ERROR [/usr/local/lib64/python2.7/site-packages/django/core/handlers/base.py:256] Internal Server Error: /admin/
Traceback (most recent call last):
  File "/usr/local/lib64/python2.7/site-packages/django/core/handlers/base.py", line 132, in get_response
    response = wrapped_callback(request, *callback_args, **callback_kwargs)
  File "/usr/local/lib64/python2.7/site-packages/django/contrib/admin/sites.py", line 254, in wrapper
    return self.admin_view(view, cacheable)(*args, **kwargs)
  File "/usr/local/lib64/python2.7/site-packages/django/utils/decorators.py", line 110, in _wrapped_view
    response = view_func(request, *args, **kwargs)
  File "/usr/local/lib64/python2.7/site-packages/django/views/decorators/cache.py", line 57, in _wrapped_view_func
    response = view_func(request, *args, **kwargs)
  File "/usr/local/lib64/python2.7/site-packages/django/contrib/admin/sites.py", line 223, in inner
    if request.path == reverse('admin:logout', current_app=self.name):
  File "/usr/local/lib64/python2.7/site-packages/django/core/urlresolvers.py", line 578, in reverse
    return force_text(iri_to_uri(resolver._reverse_with_prefix(view, prefix, *args, **kwargs)))
  File "/usr/local/lib64/python2.7/site-packages/django/core/urlresolvers.py", line 432, in _reverse_with_prefix
    self._populate()
  File "/usr/local/lib64/python2.7/site-packages/django/core/urlresolvers.py", line 307, in _populate
    for name in pattern.reverse_dict:
  File "/usr/local/lib64/python2.7/site-packages/django/core/urlresolvers.py", line 337, in reverse_dict
    self._populate()
  File "/usr/local/lib64/python2.7/site-packages/django/core/urlresolvers.py", line 307, in _populate
    for name in pattern.reverse_dict:
  File "/usr/local/lib64/python2.7/site-packages/django/core/urlresolvers.py", line 337, in reverse_dict
    self._populate()
  File "/usr/local/lib64/python2.7/site-packages/django/core/urlresolvers.py", line 284, in _populate
    for pattern in reversed(self.url_patterns):
  File "/usr/local/lib64/python2.7/site-packages/django/core/urlresolvers.py", line 410, in url_patterns
    raise ImproperlyConfigured(msg.format(name=self.urlconf_name))
ImproperlyConfigured: The included urlconf 'None' does not appear to have any patterns in it. If you see valid patterns in the file then the issue is probably caused by a circular import.
[26/Apr/2017 14:20:52] ERROR [/usr/local/lib64/python2.7/site-packages/django/core/handlers/base.py:256] Internal Server Error: /admin/
Traceback (most recent call last):
  File "/usr/local/lib64/python2.7/site-packages/django/core/handlers/base.py", line 132, in get_response
    response = wrapped_callback(request, *callback_args, **callback_kwargs)
  File "/usr/local/lib64/python2.7/site-packages/django/contrib/admin/sites.py", line 254, in wrapper
    return self.admin_view(view, cacheable)(*args, **kwargs)
  File "/usr/local/lib64/python2.7/site-packages/django/utils/decorators.py", line 110, in _wrapped_view
    response = view_func(request, *args, **kwargs)
  File "/usr/local/lib64/python2.7/site-packages/django/views/decorators/cache.py", line 57, in _wrapped_view_func
    response = view_func(request, *args, **kwargs)
  File "/usr/local/lib64/python2.7/site-packages/django/contrib/admin/sites.py", line 223, in inner
    if request.path == reverse('admin:logout', current_app=self.name):
  File "/usr/local/lib64/python2.7/site-packages/django/core/urlresolvers.py", line 578, in reverse
    return force_text(iri_to_uri(resolver._reverse_with_prefix(view, prefix, *args, **kwargs)))
  File "/usr/local/lib64/python2.7/site-packages/django/core/urlresolvers.py", line 432, in _reverse_with_prefix
    self._populate()
  File "/usr/local/lib64/python2.7/site-packages/django/core/urlresolvers.py", line 307, in _populate
    for name in pattern.reverse_dict:
  File "/usr/local/lib64/python2.7/site-packages/django/core/urlresolvers.py", line 337, in reverse_dict
    self._populate()
  File "/usr/local/lib64/python2.7/site-packages/django/core/urlresolvers.py", line 307, in _populate
    for name in pattern.reverse_dict:
  File "/usr/local/lib64/python2.7/site-packages/django/core/urlresolvers.py", line 337, in reverse_dict
    self._populate()
  File "/usr/local/lib64/python2.7/site-packages/django/core/urlresolvers.py", line 284, in _populate
    for pattern in reversed(self.url_patterns):
  File "/usr/local/lib64/python2.7/site-packages/django/core/urlresolvers.py", line 410, in url_patterns
    raise ImproperlyConfigured(msg.format(name=self.urlconf_name))
ImproperlyConfigured: The included urlconf 'None' does not appear to have any patterns in it. If you see valid patterns in the file then the issue is probably caused by a circular import.
[26/Apr/2017 14:33:50] ERROR [/usr/local/lib64/python2.7/site-packages/django/core/handlers/base.py:256] Internal Server Error: /admin/
Traceback (most recent call last):
  File "/usr/local/lib64/python2.7/site-packages/django/core/handlers/base.py", line 132, in get_response
    response = wrapped_callback(request, *callback_args, **callback_kwargs)
  File "/usr/local/lib64/python2.7/site-packages/django/contrib/admin/sites.py", line 254, in wrapper
    return self.admin_view(view, cacheable)(*args, **kwargs)
  File "/usr/local/lib64/python2.7/site-packages/django/utils/decorators.py", line 110, in _wrapped_view
    response = view_func(request, *args, **kwargs)
  File "/usr/local/lib64/python2.7/site-packages/django/views/decorators/cache.py", line 57, in _wrapped_view_func
    response = view_func(request, *args, **kwargs)
  File "/usr/local/lib64/python2.7/site-packages/django/contrib/admin/sites.py", line 223, in inner
    if request.path == reverse('admin:logout', current_app=self.name):
  File "/usr/local/lib64/python2.7/site-packages/django/core/urlresolvers.py", line 578, in reverse
    return force_text(iri_to_uri(resolver._reverse_with_prefix(view, prefix, *args, **kwargs)))
  File "/usr/local/lib64/python2.7/site-packages/django/core/urlresolvers.py", line 432, in _reverse_with_prefix
    self._populate()
  File "/usr/local/lib64/python2.7/site-packages/django/core/urlresolvers.py", line 307, in _populate
    for name in pattern.reverse_dict:
  File "/usr/local/lib64/python2.7/site-packages/django/core/urlresolvers.py", line 337, in reverse_dict
    self._populate()
  File "/usr/local/lib64/python2.7/site-packages/django/core/urlresolvers.py", line 307, in _populate
    for name in pattern.reverse_dict:
  File "/usr/local/lib64/python2.7/site-packages/django/core/urlresolvers.py", line 337, in reverse_dict
    self._populate()
  File "/usr/local/lib64/python2.7/site-packages/django/core/urlresolvers.py", line 284, in _populate
    for pattern in reversed(self.url_patterns):
  File "/usr/local/lib64/python2.7/site-packages/django/core/urlresolvers.py", line 410, in url_patterns
    raise ImproperlyConfigured(msg.format(name=self.urlconf_name))
ImproperlyConfigured: The included urlconf 'None' does not appear to have any patterns in it. If you see valid patterns in the file then the issue is probably caused by a circular import.
[26/Apr/2017 14:43:18] ERROR [/usr/local/lib64/python2.7/site-packages/django/core/handlers/base.py:256] Internal Server Error: /admin/
Traceback (most recent call last):
  File "/usr/local/lib64/python2.7/site-packages/django/core/handlers/base.py", line 132, in get_response
    response = wrapped_callback(request, *callback_args, **callback_kwargs)
  File "/usr/local/lib64/python2.7/site-packages/django/contrib/admin/sites.py", line 254, in wrapper
    return self.admin_view(view, cacheable)(*args, **kwargs)
  File "/usr/local/lib64/python2.7/site-packages/django/utils/decorators.py", line 110, in _wrapped_view
    response = view_func(request, *args, **kwargs)
  File "/usr/local/lib64/python2.7/site-packages/django/views/decorators/cache.py", line 57, in _wrapped_view_func
    response = view_func(request, *args, **kwargs)
  File "/usr/local/lib64/python2.7/site-packages/django/contrib/admin/sites.py", line 223, in inner
    if request.path == reverse('admin:logout', current_app=self.name):
  File "/usr/local/lib64/python2.7/site-packages/django/core/urlresolvers.py", line 578, in reverse
    return force_text(iri_to_uri(resolver._reverse_with_prefix(view, prefix, *args, **kwargs)))
  File "/usr/local/lib64/python2.7/site-packages/django/core/urlresolvers.py", line 432, in _reverse_with_prefix
    self._populate()
  File "/usr/local/lib64/python2.7/site-packages/django/core/urlresolvers.py", line 307, in _populate
    for name in pattern.reverse_dict:
  File "/usr/local/lib64/python2.7/site-packages/django/core/urlresolvers.py", line 337, in reverse_dict
    self._populate()
  File "/usr/local/lib64/python2.7/site-packages/django/core/urlresolvers.py", line 307, in _populate
    for name in pattern.reverse_dict:
  File "/usr/local/lib64/python2.7/site-packages/django/core/urlresolvers.py", line 337, in reverse_dict
    self._populate()
  File "/usr/local/lib64/python2.7/site-packages/django/core/urlresolvers.py", line 284, in _populate
    for pattern in reversed(self.url_patterns):
  File "/usr/local/lib64/python2.7/site-packages/django/core/urlresolvers.py", line 410, in url_patterns
    raise ImproperlyConfigured(msg.format(name=self.urlconf_name))
ImproperlyConfigured: The included urlconf 'None' does not appear to have any patterns in it. If you see valid patterns in the file then the issue is probably caused by a circular import.
[26/Apr/2017 14:56:08] ERROR [/usr/local/lib64/python2.7/site-packages/django/core/handlers/base.py:256] Internal Server Error: /admin/
Traceback (most recent call last):
  File "/usr/local/lib64/python2.7/site-packages/django/core/handlers/base.py", line 132, in get_response
    response = wrapped_callback(request, *callback_args, **callback_kwargs)
  File "/usr/local/lib64/python2.7/site-packages/django/contrib/admin/sites.py", line 254, in wrapper
    return self.admin_view(view, cacheable)(*args, **kwargs)
  File "/usr/local/lib64/python2.7/site-packages/django/utils/decorators.py", line 110, in _wrapped_view
    response = view_func(request, *args, **kwargs)
  File "/usr/local/lib64/python2.7/site-packages/django/views/decorators/cache.py", line 57, in _wrapped_view_func
    response = view_func(request, *args, **kwargs)
  File "/usr/local/lib64/python2.7/site-packages/django/contrib/admin/sites.py", line 223, in inner
    if request.path == reverse('admin:logout', current_app=self.name):
  File "/usr/local/lib64/python2.7/site-packages/django/core/urlresolvers.py", line 578, in reverse
    return force_text(iri_to_uri(resolver._reverse_with_prefix(view, prefix, *args, **kwargs)))
  File "/usr/local/lib64/python2.7/site-packages/django/core/urlresolvers.py", line 432, in _reverse_with_prefix
    self._populate()
  File "/usr/local/lib64/python2.7/site-packages/django/core/urlresolvers.py", line 307, in _populate
    for name in pattern.reverse_dict:
  File "/usr/local/lib64/python2.7/site-packages/django/core/urlresolvers.py", line 337, in reverse_dict
    self._populate()
  File "/usr/local/lib64/python2.7/site-packages/django/core/urlresolvers.py", line 307, in _populate
    for name in pattern.reverse_dict:
  File "/usr/local/lib64/python2.7/site-packages/django/core/urlresolvers.py", line 337, in reverse_dict
    self._populate()
  File "/usr/local/lib64/python2.7/site-packages/django/core/urlresolvers.py", line 284, in _populate
    for pattern in reversed(self.url_patterns):
  File "/usr/local/lib64/python2.7/site-packages/django/core/urlresolvers.py", line 410, in url_patterns
    raise ImproperlyConfigured(msg.format(name=self.urlconf_name))
ImproperlyConfigured: The included urlconf 'None' does not appear to have any patterns in it. If you see valid patterns in the file then the issue is probably caused by a circular import.
[26/Apr/2017 16:31:51] ERROR [/usr/local/lib64/python2.7/site-packages/django/core/handlers/base.py:256] Internal Server Error: /twitter_count/realtime_jp/
Traceback (most recent call last):
  File "/usr/local/lib64/python2.7/site-packages/django/core/handlers/base.py", line 132, in get_response
    response = wrapped_callback(request, *callback_args, **callback_kwargs)
  File "/usr/local/lib64/python2.7/site-packages/django/views/generic/base.py", line 71, in view
    return self.dispatch(request, *args, **kwargs)
  File "/usr/local/lib64/python2.7/site-packages/django/views/generic/base.py", line 89, in dispatch
    return handler(request, *args, **kwargs)
  File "/var/www/instag_new/src/twitter_count/views.py", line 50, in get
    twitter_ranking_list = twitter_ranking_list[int(url_from)-1:url_to]
ValueError: invalid literal for int() with base 10: ''
[28/Apr/2017 19:03:36] ERROR [/usr/local/lib64/python2.7/site-packages/django/core/handlers/base.py:256] Internal Server Error: /felica/
Traceback (most recent call last):
  File "/usr/local/lib64/python2.7/site-packages/django/core/handlers/base.py", line 151, in get_response
    % (callback.__module__, view_name))
ValueError: The view felica.views.Felica didn't return an HttpResponse object. It returned None instead.
[28/Apr/2017 19:03:38] ERROR [/usr/local/lib64/python2.7/site-packages/django/core/handlers/base.py:256] Internal Server Error: /felica/
Traceback (most recent call last):
  File "/usr/local/lib64/python2.7/site-packages/django/core/handlers/base.py", line 151, in get_response
    % (callback.__module__, view_name))
ValueError: The view felica.views.Felica didn't return an HttpResponse object. It returned None instead.
[29/Apr/2017 18:22:54] ERROR [/usr/local/lib64/python2.7/site-packages/django/core/handlers/base.py:256] Internal Server Error: /twitter_count/realtime_ko/
Traceback (most recent call last):
  File "/usr/local/lib64/python2.7/site-packages/django/core/handlers/base.py", line 132, in get_response
    response = wrapped_callback(request, *callback_args, **callback_kwargs)
  File "/usr/local/lib64/python2.7/site-packages/django/views/generic/base.py", line 71, in view
    return self.dispatch(request, *args, **kwargs)
  File "/usr/local/lib64/python2.7/site-packages/django/views/generic/base.py", line 89, in dispatch
    return handler(request, *args, **kwargs)
  File "/var/www/instag_new/src/twitter_count/views.py", line 81, in get
    twitter_ranking_list = twitter_ranking_list[int(url_from)-1:url_to]
ValueError: invalid literal for int() with base 10: ''
[01/May/2017 13:38:17] ERROR [/usr/local/lib64/python2.7/site-packages/django/core/handlers/base.py:256] Internal Server Error: /felica/
Traceback (most recent call last):
  File "/usr/local/lib64/python2.7/site-packages/django/core/handlers/base.py", line 132, in get_response
    response = wrapped_callback(request, *callback_args, **callback_kwargs)
  File "/usr/local/lib64/python2.7/site-packages/django/views/generic/base.py", line 71, in view
    return self.dispatch(request, *args, **kwargs)
  File "/usr/local/lib64/python2.7/site-packages/django/views/generic/base.py", line 89, in dispatch
    return handler(request, *args, **kwargs)
  File "/var/www/instag_new/src/felica/views.py", line 46, in get
    fm.member_name
  File "/var/www/instag_new/src/felica/models.py", line 84, in set_work_time
    return result
UnboundLocalError: local variable 'result' referenced before assignment
[01/May/2017 13:38:22] ERROR [/usr/local/lib64/python2.7/site-packages/django/core/handlers/base.py:256] Internal Server Error: /felica/
Traceback (most recent call last):
  File "/usr/local/lib64/python2.7/site-packages/django/core/handlers/base.py", line 151, in get_response
    % (callback.__module__, view_name))
ValueError: The view felica.views.Felica didn't return an HttpResponse object. It returned None instead.
[01/May/2017 13:45:37] ERROR [/usr/local/lib64/python2.7/site-packages/django/core/handlers/base.py:256] Internal Server Error: /felica/
Traceback (most recent call last):
  File "/usr/local/lib64/python2.7/site-packages/django/core/handlers/base.py", line 132, in get_response
    response = wrapped_callback(request, *callback_args, **callback_kwargs)
  File "/usr/local/lib64/python2.7/site-packages/django/views/generic/base.py", line 71, in view
    return self.dispatch(request, *args, **kwargs)
  File "/usr/local/lib64/python2.7/site-packages/django/views/generic/base.py", line 89, in dispatch
    return handler(request, *args, **kwargs)
  File "/var/www/instag_new/src/felica/views.py", line 46, in get
    fm.member_name
  File "/var/www/instag_new/src/felica/models.py", line 84, in set_work_time
    return result
UnboundLocalError: local variable 'result' referenced before assignment
[01/May/2017 13:51:30] ERROR [/usr/local/lib64/python2.7/site-packages/django/core/handlers/base.py:256] Internal Server Error: /felica/
Traceback (most recent call last):
  File "/usr/local/lib64/python2.7/site-packages/django/core/handlers/base.py", line 151, in get_response
    % (callback.__module__, view_name))
ValueError: The view felica.views.Felica didn't return an HttpResponse object. It returned None instead.
[01/May/2017 13:52:04] ERROR [/usr/local/lib64/python2.7/site-packages/django/core/handlers/base.py:256] Internal Server Error: /felica/felica/member/edit/2
Traceback (most recent call last):
  File "/usr/local/lib64/python2.7/site-packages/django/core/handlers/base.py", line 132, in get_response
    response = wrapped_callback(request, *callback_args, **callback_kwargs)
  File "/usr/local/lib64/python2.7/site-packages/django/views/generic/base.py", line 71, in view
    return self.dispatch(request, *args, **kwargs)
  File "/usr/local/lib/python2.7/site-packages/braces/views/_access.py", line 98, in dispatch
    request, *args, **kwargs)
  File "/usr/local/lib64/python2.7/site-packages/django/views/generic/base.py", line 89, in dispatch
    return handler(request, *args, **kwargs)
  File "/var/www/instag_new/src/felica/views.py", line 71, in post
    result = FelicaMember.update(user.id, request.POST, kwargs['id'])
  File "/var/www/instag_new/src/felica/models.py", line 165, in update
    result.save()
  File "/usr/local/lib64/python2.7/site-packages/django/db/models/base.py", line 734, in save
    force_update=force_update, update_fields=update_fields)
  File "/usr/local/lib64/python2.7/site-packages/django/db/models/base.py", line 762, in save_base
    updated = self._save_table(raw, cls, force_insert, force_update, using, update_fields)
  File "/usr/local/lib64/python2.7/site-packages/django/db/models/base.py", line 827, in _save_table
    forced_update)
  File "/usr/local/lib64/python2.7/site-packages/django/db/models/base.py", line 877, in _do_update
    return filtered._update(values) > 0
  File "/usr/local/lib64/python2.7/site-packages/django/db/models/query.py", line 580, in _update
    return query.get_compiler(self.db).execute_sql(CURSOR)
  File "/usr/local/lib64/python2.7/site-packages/django/db/models/sql/compiler.py", line 1062, in execute_sql
    cursor = super(SQLUpdateCompiler, self).execute_sql(result_type)
  File "/usr/local/lib64/python2.7/site-packages/django/db/models/sql/compiler.py", line 829, in execute_sql
    sql, params = self.as_sql()
  File "/usr/local/lib64/python2.7/site-packages/django/db/models/sql/compiler.py", line 1030, in as_sql
    val = field.get_db_prep_save(val, connection=self.connection)
  File "/usr/local/lib64/python2.7/site-packages/django/db/models/fields/__init__.py", line 710, in get_db_prep_save
    prepared=False)
  File "/usr/local/lib64/python2.7/site-packages/django/db/models/fields/__init__.py", line 702, in get_db_prep_value
    value = self.get_prep_value(value)
  File "/usr/local/lib64/python2.7/site-packages/django/db/models/fields/__init__.py", line 1868, in get_prep_value
    return int(value)
ValueError: invalid literal for int() with base 10: ''
